<?xml version="1.0"?>
<robot name="physics">

  <material name="rubber">
    <unreal_material path="Material'/AirSim/VehicleAdv/SUV/AutomotiveMaterials/Materials/Reflector/M_Reflector.M_Reflector'" />
  </material>
  <material name="metal">
    <unreal_material path="Material'/AirSim/VehicleAdv/SUV/AutomotiveMaterials/Materials/Metal/M_Metal.M_Metal'" />
  </material>
  <material name="reflector">
    <unreal_material path="Material'/AirSim/VehicleAdv/SUV/AutomotiveMaterials/Materials/Reflector/M_Reflector.M_Reflector'" />
  </material>

  <link name="top_ring">
    <visual>
      <geometry>
        <!--UPDATE THE PATHS TO POINT TO THE ABSOLUTE LOCATION OF THE STL FILES ON DISK-->
        <mesh type="stl_ascii" location="E:\A_UnrealProject\interiorsim_demo\Examples\UrdfBot\LunabotParts\Frame3.STL" reverse_normals="true" scale_factor="50" />
      </geometry>
      <material name="metal" />
    </visual>
    <collision>
      <geometry>
        <mesh type="stl_ascii" location="E:\A_UnrealProject\interiorsim_demo\Examples\UrdfBot\LunabotParts\Frame3.STL" reverse_normals="true" scale_factor="50" dynamic_collision_type="vhacd" vhacd_concavity="0.2" vhacd_output_folder_path="E:\A_UnrealProject\interiorsim_demo\Examples\UrdfBot\LunabotParts\vhacd_bucket" />
      </geometry>
    </collision>
    <inertial>
      <mass value="20" />
      <inertia ixx="1.0" ixy="0.0" ixz="0.0" iyy="1.0" iyz="0.0" izz="1.0" />
    </inertial>
  </link>

  <link name="back_left_pivot">
    <visual>
      <geometry>
        <mesh type="stl_ascii" location="E:\A_UnrealProject\interiorsim_demo\Examples\UrdfBot\LunabotParts\SquareWheelPivot.stl" reverse_normals="true" scale_factor="50" />
      </geometry>
      <material name="metal" />
    </visual>
    <inertial>
      <mass value="1" />
      <inertia ixx="1.0" ixy="0.0" ixz="0.0" iyy="1.0" iyz="0.0" izz="1.0" />
    </inertial>
  </link>

  <joint name="top_ring_to_back_left_pivot" type="revolute">
    <parent link="top_ring" />
    <child link="back_left_pivot" />
    <origin rpy="-1.57079 0 0" xyz="0.05 0.05 0.1" />
    <axis rpy="0 0 0" rpy="0 0 0" xyz="0 0 -1" />
    <limit lower="0" upper="1.57079" effort="10000" velocity="1" />
  </joint>

  <link name="back_left_wheel">
    <visual>
      <geometry>
        <cylinder length="0.1" radius="0.1" />
      </geometry>
      <material name="rubber" />
    </visual>
    <inertial>
      <mass value="1" />
      <inertia ixx="1.0" ixy="0.0" ixz="0.0" iyy="1.0" iyz="0.0" izz="1.0" />
    </inertial>
  </link>

  <joint name="back_left_pivot_to_wheel" type="continuous">
    <parent link="back_left_pivot" />
    <child link="back_left_wheel" />
    <origin rpy="0 0 0" xyz="0.01 0.05 0.3" />
    <axis rpy="0 0 0" rpy="0 0 0" xyz="0 0 -1" />
    <limit lower="0" upper="0" effort="20" velocity="0.3" />
  </joint>

  <link name="back_right_pivot">
    <visual>
      <geometry>
        <mesh type="stl_ascii" location="E:\A_UnrealProject\interiorsim_demo\Examples\UrdfBot\LunabotParts\SquareWheelPivot.stl" reverse_normals="true" scale_factor="50" />
      </geometry>
      <material name="metal" />
    </visual>
    <inertial>
      <mass value="1" />
      <inertia ixx="1.0" ixy="0.0" ixz="0.0" iyy="1.0" iyz="0.0" izz="1.0" />
    </inertial>
  </link>

  <joint name="top_ring_to_back_right_pivot" type="revolute">
    <parent link="top_ring" />
    <child link="back_right_pivot" />
    <origin rpy="1.57079 0 0" xyz="0.05 0.55 0.2" />
    <axis rpy="0 0 0" rpy="0 0 0" xyz="0 0 1" />
    <limit lower="0" upper="1.57079" effort="10000" velocity="1" />
  </joint>

  <link name="back_right_wheel">
    <visual>
      <geometry>
        <cylinder length="0.1" radius="0.1" />
      </geometry>
      <material name="rubber" />
    </visual>

    <inertial>
      <mass value="1" />
      <inertia ixx="1.0" ixy="0.0" ixz="0.0" iyy="1.0" iyz="0.0" izz="1.0" />
    </inertial>
  </link>

  <joint name="back_right_pivot_to_wheel" type="continuous">
    <parent link="back_right_pivot" />
    <child link="back_right_wheel" />
    <origin rpy="0 0 0" xyz="0.01 0.05 0.3" />
    <axis rpy="0 0 0" rpy="0 0 0" xyz="0 0 1" />
    <limit lower="0" upper="0" effort="20" velocity="0.3" />
  </joint>

  <link name="front_left_pivot">
    <visual>
      <geometry>
        <mesh type="stl_ascii" location="E:\A_UnrealProject\interiorsim_demo\Examples\UrdfBot\LunabotParts\SquareWheelPivot.stl" reverse_normals="true" scale_factor="50" />
      </geometry>
      <material name="metal" />
    </visual>
    <inertial>
      <mass value="1" />
      <inertia ixx="1.0" ixy="0.0" ixz="0.0" iyy="1.0" iyz="0.0" izz="1.0" />
    </inertial>
  </link>

  <joint name="top_ring_to_front_left_pivot" type="revolute">
    <parent link="top_ring" />
    <child link="front_left_pivot" />
    <origin rpy="-1.57079 0 0" xyz="0.55 0.05 0.1" />
    <axis rpy="0 0 0" rpy="0 0 0" xyz="0 0 1" />
    <limit lower="0" upper="1.57079" effort="10000" velocity="1" />
  </joint>

  <link name="front_left_wheel">
    <visual>
      <geometry>
        <cylinder length="0.1" radius="0.1" />
      </geometry>
      <material name="rubber" />
    </visual>
    <inertial>
      <mass value="1" />
      <inertia ixx="1.0" ixy="0.0" ixz="0.0" iyy="1.0" iyz="0.0" izz="1.0" />
    </inertial>
  </link>

  <joint name="front_left_pivot_to_wheel" type="continuous">
    <parent link="front_left_pivot" />
    <child link="front_left_wheel" />
    <origin rpy="0 0 0" xyz="0.01 0.05 0.3" />
    <axis rpy="0 0 0" rpy="0 0 0" xyz="0 0 -1" />
    <limit lower="0" upper="0" effort="20" velocity="0.3" />
  </joint>

  <link name="front_right_pivot">
    <visual>
      <geometry>
        <mesh type="stl_ascii" location="E:\A_UnrealProject\interiorsim_demo\Examples\UrdfBot\LunabotParts\SquareWheelPivot.stl" reverse_normals="true" scale_factor="50" />
      </geometry>
      <material name="metal" />
    </visual>
    <inertial>
      <mass value="1" />
      <inertia ixx="1.0" ixy="0.0" ixz="0.0" iyy="1.0" iyz="0.0" izz="1.0" />
    </inertial>
  </link>

  <joint name="top_ring_to_front_right_pivot" type="revolute">
    <parent link="top_ring" />
    <child link="front_right_pivot" />
    <origin rpy="1.57079 0 0" xyz="0.55 0.55 0.2" />
    <axis rpy="0 0 0" rpy="0 0 0" xyz="0 0 -1" />
    <limit lower="0" upper="1.57079" effort="10000" velocity="1" />
  </joint>

  <link name="front_right_wheel">
    <visual>
      <geometry>
        <cylinder length="0.1" radius="0.1" />
      </geometry>
      <material name="rubber" />
    </visual>
    <inertial>
      <mass value="1" />
      <inertia ixx="1.0" ixy="0.0" ixz="0.0" iyy="1.0" iyz="0.0" izz="1.0" />
    </inertial>
  </link>

  <joint name="front_right_pivot_to_wheel" type="continuous">
    <parent link="front_right_pivot" />
    <child link="front_right_wheel" />
    <origin rpy="0 0 0" xyz="0.01 0.05 0.3" />
    <axis rpy="0 0 0" rpy="0 0 0" xyz="0 0 1" />
    <limit lower="0" upper="0" effort="20" velocity="0.3" />
  </joint>

  <link name="h_bar">
    <visual>
      <geometry>
        <mesh type="stl_ascii" location="E:\A_UnrealProject\interiorsim_demo\Examples\UrdfBot\LunabotParts\HBar.stl" reverse_normals="true" scale_factor="50" />
      </geometry>
      <material name="metal" />
    </visual>
    <inertial>
      <mass value="1" />
      <inertia ixx="1.0" ixy="0.0" ixz="0.0" iyy="1.0" iyz="0.0" izz="1.0" />
    </inertial>
  </link>

  <joint name="top_ring_to_hbar" type="revolute">
    <parent link="top_ring" />
    <child link="h_bar" />
    <origin rpy="1.57079 0 0" xyz="0 -0.05 1.1" />
    <axis rpy="0 0 0" rpy="0 0 0" xyz="0 -1 0" />
    <limit lower="-0.5" upper="0.1" effort="10000" velocity="0.2" />
  </joint>

  <link name="bucket">
    <visual>
      <geometry>
        <mesh type="stl_ascii" location="E:\A_UnrealProject\interiorsim_demo\Examples\UrdfBot\LunabotParts\BucketProperCenter.stl" reverse_normals="true" scale_factor="50" />
      </geometry>
      <material name="metal" />
    </visual>
    <collision>
      <geometry>
        <mesh type="stl_ascii" location="E:\A_UnrealProject\interiorsim_demo\Examples\UrdfBot\LunabotParts\BucketProperCenter.STL" reverse_normals="true" scale_factor="50" dynamic_collision_type="vhacd" vhacd_concavity="0.2" vhacd_output_folder_path="E:\A_UnrealProject\interiorsim_demo\Examples\UrdfBot\LunabotParts\vhacd_bucket" />
      </geometry>
    </collision>
    <inertial>
      <mass value="1" />
      <inertia ixx="1.0" ixy="0.0" ixz="0.0" iyy="1.0" iyz="0.0" izz="1.0" />
    </inertial>
  </link>

  <joint name="hbar_to_bucket" type="revolute">
    <parent link="h_bar" />
    <child link="bucket" />
    <origin rpy="1.57079 0 1.57079" xyz="1.65 0.05 0.35" />
    <axis rpy="0 0 0" rpy="0 0 0" xyz="0 0 -1" />
    <limit lower="-0.2" upper="0.2" effort="10000" velocity="0.2" />
  </joint>


</robot>