<mujoco>
	<asset>
		<include file="output/Unknown/Kitchen_Extractor/Door_13/cvx/Door_13_assets.xml" />
		<include file="output/Unknown/Kitchen_Extractor/Door_14/cvx/Door_14_assets.xml" />
		<include file="output/Unknown/Kitchen_Extractor/Door_15/cvx/Door_15_assets.xml" />
		<include file="output/Unknown/Kitchen_Extractor/Door_12/cvx/Door_12_assets.xml" />
		<include file="output/Unknown/Kitchen_Extractor/Door_01/cvx/Door_01_assets.xml" />
		<include file="output/Unknown/Kitchen_Extractor/Door_06/cvx/Door_06_assets.xml" />
		<include file="output/Unknown/Kitchen_Extractor/Door_08/cvx/Door_08_assets.xml" />
		<include file="output/Unknown/Kitchen_Extractor/Door_09/cvx/Door_09_assets.xml" />
		<include file="output/Unknown/Kitchen_Extractor/Door_07/cvx/Door_07_assets.xml" />
		<include file="output/Unknown/Kitchen_Extractor/Door_10/cvx/Door_10_assets.xml" />
		<include file="output/Unknown/Kitchen_Extractor/Door_11/cvx/Door_11_assets.xml" />
		<include file="output/Unknown/Kitchen_Extractor/Door_16/cvx/Door_16_assets.xml" />
		<include file="output/Unknown/Kitchen_Extractor/Kitchen_Extractor_Base/cvx/Kitchen_Extractor_Base_assets.xml" />
		<include file="output/Unknown/Kitchen_Extractor/Door_05/cvx/Door_05_assets.xml" />
		<include file="output/Unknown/Kitchen_Extractor/Door_02/cvx/Door_02_assets.xml" />
		<include file="output/Unknown/Kitchen_Extractor/Door_03/cvx/Door_03_assets.xml" />
		<include file="output/Unknown/Kitchen_Extractor/Door_04/cvx/Door_04_assets.xml" />
	</asset>
	<worldbody>
		<body name="Kitchen_Extractor" pos="-8.208234 -1.407807 2.544017" quat="1.000000 0.000000 0.000000 0.000000">
			<body name="Kitchen_Extractor/Door_13" pos="3.307953 0.906106 0.654863" quat="0.000000 0.000000 0.000000 -1.000000">
				<joint name="Kitchen_Extractor/PhysicsConstraint_door_13_x_revolute" type="hinge" pos="0.00000 0.00000 0.00000" axis="-0.00000 0.00000 -1.00000" range="-0.08727 1.48353" />
				<include file="output/Unknown/Kitchen_Extractor/Door_13/cvx/Door_13_body.xml" />
			</body>
			<body name="Kitchen_Extractor/Door_14" pos="3.307953 2.094399 0.654863" quat="0.000000 0.000000 0.000000 -1.000000">
				<joint name="Kitchen_Extractor/PhysicsConstraint_door_14_x_revolute" type="hinge" pos="0.00000 0.00000 0.00000" axis="0.00000 -0.00000 -1.00000" range="-1.48353 0.08727" />
				<include file="output/Unknown/Kitchen_Extractor/Door_14/cvx/Door_14_body.xml" />
			</body>
			<body name="Kitchen_Extractor/Door_15" pos="3.307953 0.907517 -0.063890" quat="0.000000 0.000000 0.000000 -1.000000">
				<joint name="Kitchen_Extractor/PhysicsConstraint_door_15_x_revolute" type="hinge" pos="0.00000 0.00000 0.00000" axis="-0.00000 0.00000 -1.00000" range="-0.08727 1.48353" />
				<include file="output/Unknown/Kitchen_Extractor/Door_15/cvx/Door_15_body.xml" />
			</body>
			<body name="Kitchen_Extractor/Door_12" pos="3.307953 0.805197 -0.040163" quat="0.000000 0.000000 0.000000 -1.000000">
				<joint name="Kitchen_Extractor/PhysicsConstraint_door_12_x_revolute" type="hinge" pos="0.00000 0.00000 0.00000" axis="0.00000 -0.00000 -1.00000" range="-1.48353 0.08727" />
				<include file="output/Unknown/Kitchen_Extractor/Door_12/cvx/Door_12_body.xml" />
			</body>
			<body name="Kitchen_Extractor/Door_01" pos="3.307953 -4.966123 0.654863" quat="0.000000 0.000000 0.000000 -1.000000">
				<joint name="Kitchen_Extractor/PhysicsConstraint_door_01_x_revolute" type="hinge" pos="0.00000 0.00000 0.00000" axis="-0.00000 0.00000 -1.00000" range="-0.08727 1.48353" />
				<include file="output/Unknown/Kitchen_Extractor/Door_01/cvx/Door_01_body.xml" />
			</body>
			<body name="Kitchen_Extractor/Door_06" pos="3.306660 -0.491811 0.655309" quat="0.000000 0.000000 0.000000 -1.000000">
				<joint name="Kitchen_Extractor/PhysicsConstraint_door_06_x_revolute" type="hinge" pos="0.00000 0.00000 0.00000" axis="0.00000 -0.00000 -1.00000" range="-1.48353 0.08727" />
				<include file="output/Unknown/Kitchen_Extractor/Door_06/cvx/Door_06_body.xml" />
			</body>
			<body name="Kitchen_Extractor/Door_08" pos="3.306660 -0.489843 -0.039717" quat="0.000000 0.000000 0.000000 -1.000000">
				<joint name="Kitchen_Extractor/PhysicsConstraint_door_08_x_revolute" type="hinge" pos="0.00000 0.00000 0.00000" axis="0.00000 -0.00000 -1.00000" range="-1.48353 0.08727" />
				<include file="output/Unknown/Kitchen_Extractor/Door_08/cvx/Door_08_body.xml" />
			</body>
			<body name="Kitchen_Extractor/Door_09" pos="3.307953 -0.367814 0.654863" quat="0.000000 0.000000 0.000000 -1.000000">
				<joint name="Kitchen_Extractor/PhysicsConstraint_door_09_x_revolute" type="hinge" pos="0.00000 0.00000 0.00000" axis="-0.00000 0.00000 -1.00000" range="-0.08727 1.48353" />
				<include file="output/Unknown/Kitchen_Extractor/Door_09/cvx/Door_09_body.xml" />
			</body>
			<body name="Kitchen_Extractor/Door_07" pos="3.306660 -1.660128 -0.063444" quat="0.000000 0.000000 0.000000 -1.000000">
				<joint name="Kitchen_Extractor/PhysicsConstraint_door_07_x_revolute" type="hinge" pos="0.00000 0.00000 0.00000" axis="-0.00000 0.00000 -1.00000" range="-0.08727 1.48353" />
				<include file="output/Unknown/Kitchen_Extractor/Door_07/cvx/Door_07_body.xml" />
			</body>
			<body name="Kitchen_Extractor/Door_10" pos="3.307953 0.805862 0.654863" quat="0.000000 0.000000 0.000000 -1.000000">
				<joint name="Kitchen_Extractor/PhysicsConstraint_door_10_x_revolute" type="hinge" pos="0.00000 0.00000 0.00000" axis="0.00000 -0.00000 -1.00000" range="-1.48353 0.08727" />
				<include file="output/Unknown/Kitchen_Extractor/Door_10/cvx/Door_10_body.xml" />
			</body>
			<body name="Kitchen_Extractor/Door_11" pos="3.307953 -0.368783 -0.063890" quat="0.000000 0.000000 0.000000 -1.000000">
				<joint name="Kitchen_Extractor/PhysicsConstraint_door_11_x_revolute" type="hinge" pos="0.00000 0.00000 0.00000" axis="-0.00000 0.00000 -1.00000" range="-0.08727 1.48353" />
				<include file="output/Unknown/Kitchen_Extractor/Door_11/cvx/Door_11_body.xml" />
			</body>
			<body name="Kitchen_Extractor/Door_16" pos="3.307953 2.090873 -0.043043" quat="0.000000 0.000000 0.000000 -1.000000">
				<joint name="Kitchen_Extractor/PhysicsConstraint_door_16_x_revolute" type="hinge" pos="0.00000 0.00000 0.00000" axis="-0.00000 0.00000 -1.00000" range="-1.48353 0.08727" />
				<include file="output/Unknown/Kitchen_Extractor/Door_16/cvx/Door_16_body.xml" />
			</body>
			<include file="output/Unknown/Kitchen_Extractor/Kitchen_Extractor_Base/cvx/Kitchen_Extractor_Base_body.xml" />
			<body name="Kitchen_Extractor/Door_05" pos="3.306660 -1.660128 0.653929" quat="0.000000 0.000000 0.000000 -1.000000">
				<joint name="Kitchen_Extractor/PhysicsConstraint_door_05_x_revolute" type="hinge" pos="0.00000 0.00000 0.00000" axis="-0.00000 0.00000 -1.00000" range="-0.08727 1.48353" />
				<include file="output/Unknown/Kitchen_Extractor/Door_05/cvx/Door_05_body.xml" />
			</body>
			<body name="Kitchen_Extractor/Door_02" pos="3.307953 -3.866093 0.655283" quat="0.000000 0.000000 0.000000 -1.000000">
				<joint name="Kitchen_Extractor/PhysicsConstraint_door_02_x_revolute" type="hinge" pos="0.00000 0.00000 0.00000" axis="0.00000 -0.00000 -1.00000" range="-1.48353 0.08727" />
				<include file="output/Unknown/Kitchen_Extractor/Door_02/cvx/Door_02_body.xml" />
			</body>
			<body name="Kitchen_Extractor/Door_03" pos="3.307953 -4.966123 -0.063890" quat="0.000000 0.000000 0.000000 -1.000000">
				<joint name="Kitchen_Extractor/PhysicsConstraint_door_03_x_revolute" type="hinge" pos="0.00000 0.00000 0.00000" axis="-0.00000 0.00000 -1.00000" range="-0.08727 1.48353" />
				<include file="output/Unknown/Kitchen_Extractor/Door_03/cvx/Door_03_body.xml" />
			</body>
			<body name="Kitchen_Extractor/Door_04" pos="3.307953 -3.866093 -0.063890" quat="0.000000 0.000000 0.000000 -1.000000">
				<joint name="Kitchen_Extractor/PhysicsConstraint_door_04_x_revolute" type="hinge" pos="0.00000 0.00000 0.00000" axis="0.00000 -0.00000 -1.00000" range="-1.48353 0.08727" />
				<include file="output/Unknown/Kitchen_Extractor/Door_04/cvx/Door_04_body.xml" />
			</body>
		</body>
	</worldbody>
	<contact>
		<exclude body1="Kitchen_Extractor/Door_04" body2="Kitchen_Extractor/Door_03" />
		<exclude body1="Kitchen_Extractor/Door_04" body2="Kitchen_Extractor/Door_02" />
		<exclude body1="Kitchen_Extractor/Door_04" body2="Kitchen_Extractor/Door_05" />
		<exclude body1="Kitchen_Extractor/Door_04" body2="Kitchen_Extractor/Door_16" />
		<exclude body1="Kitchen_Extractor/Door_04" body2="Kitchen_Extractor/Door_11" />
		<exclude body1="Kitchen_Extractor/Door_04" body2="Kitchen_Extractor/Door_10" />
		<exclude body1="Kitchen_Extractor/Door_04" body2="Kitchen_Extractor/Door_07" />
		<exclude body1="Kitchen_Extractor/Door_04" body2="Kitchen_Extractor/Door_09" />
		<exclude body1="Kitchen_Extractor/Door_04" body2="Kitchen_Extractor/Door_08" />
		<exclude body1="Kitchen_Extractor/Door_04" body2="Kitchen_Extractor/Door_06" />
		<exclude body1="Kitchen_Extractor/Door_04" body2="Kitchen_Extractor/Door_01" />
		<exclude body1="Kitchen_Extractor/Door_04" body2="Kitchen_Extractor/Door_12" />
		<exclude body1="Kitchen_Extractor/Door_04" body2="Kitchen_Extractor/Door_15" />
		<exclude body1="Kitchen_Extractor/Door_04" body2="Kitchen_Extractor/Door_14" />
		<exclude body1="Kitchen_Extractor/Door_04" body2="Kitchen_Extractor/Door_13" />
		<exclude body1="Kitchen_Extractor/Door_03" body2="Kitchen_Extractor/Door_02" />
		<exclude body1="Kitchen_Extractor/Door_03" body2="Kitchen_Extractor/Door_05" />
		<exclude body1="Kitchen_Extractor/Door_03" body2="Kitchen_Extractor/Door_16" />
		<exclude body1="Kitchen_Extractor/Door_03" body2="Kitchen_Extractor/Door_11" />
		<exclude body1="Kitchen_Extractor/Door_03" body2="Kitchen_Extractor/Door_10" />
		<exclude body1="Kitchen_Extractor/Door_03" body2="Kitchen_Extractor/Door_07" />
		<exclude body1="Kitchen_Extractor/Door_03" body2="Kitchen_Extractor/Door_09" />
		<exclude body1="Kitchen_Extractor/Door_03" body2="Kitchen_Extractor/Door_08" />
		<exclude body1="Kitchen_Extractor/Door_03" body2="Kitchen_Extractor/Door_06" />
		<exclude body1="Kitchen_Extractor/Door_03" body2="Kitchen_Extractor/Door_01" />
		<exclude body1="Kitchen_Extractor/Door_03" body2="Kitchen_Extractor/Door_12" />
		<exclude body1="Kitchen_Extractor/Door_03" body2="Kitchen_Extractor/Door_15" />
		<exclude body1="Kitchen_Extractor/Door_03" body2="Kitchen_Extractor/Door_14" />
		<exclude body1="Kitchen_Extractor/Door_03" body2="Kitchen_Extractor/Door_13" />
		<exclude body1="Kitchen_Extractor/Door_02" body2="Kitchen_Extractor/Door_05" />
		<exclude body1="Kitchen_Extractor/Door_02" body2="Kitchen_Extractor/Door_16" />
		<exclude body1="Kitchen_Extractor/Door_02" body2="Kitchen_Extractor/Door_11" />
		<exclude body1="Kitchen_Extractor/Door_02" body2="Kitchen_Extractor/Door_10" />
		<exclude body1="Kitchen_Extractor/Door_02" body2="Kitchen_Extractor/Door_07" />
		<exclude body1="Kitchen_Extractor/Door_02" body2="Kitchen_Extractor/Door_09" />
		<exclude body1="Kitchen_Extractor/Door_02" body2="Kitchen_Extractor/Door_08" />
		<exclude body1="Kitchen_Extractor/Door_02" body2="Kitchen_Extractor/Door_06" />
		<exclude body1="Kitchen_Extractor/Door_02" body2="Kitchen_Extractor/Door_01" />
		<exclude body1="Kitchen_Extractor/Door_02" body2="Kitchen_Extractor/Door_12" />
		<exclude body1="Kitchen_Extractor/Door_02" body2="Kitchen_Extractor/Door_15" />
		<exclude body1="Kitchen_Extractor/Door_02" body2="Kitchen_Extractor/Door_14" />
		<exclude body1="Kitchen_Extractor/Door_02" body2="Kitchen_Extractor/Door_13" />
		<exclude body1="Kitchen_Extractor/Door_05" body2="Kitchen_Extractor/Door_16" />
		<exclude body1="Kitchen_Extractor/Door_05" body2="Kitchen_Extractor/Door_11" />
		<exclude body1="Kitchen_Extractor/Door_05" body2="Kitchen_Extractor/Door_10" />
		<exclude body1="Kitchen_Extractor/Door_05" body2="Kitchen_Extractor/Door_07" />
		<exclude body1="Kitchen_Extractor/Door_05" body2="Kitchen_Extractor/Door_09" />
		<exclude body1="Kitchen_Extractor/Door_05" body2="Kitchen_Extractor/Door_08" />
		<exclude body1="Kitchen_Extractor/Door_05" body2="Kitchen_Extractor/Door_06" />
		<exclude body1="Kitchen_Extractor/Door_05" body2="Kitchen_Extractor/Door_01" />
		<exclude body1="Kitchen_Extractor/Door_05" body2="Kitchen_Extractor/Door_12" />
		<exclude body1="Kitchen_Extractor/Door_05" body2="Kitchen_Extractor/Door_15" />
		<exclude body1="Kitchen_Extractor/Door_05" body2="Kitchen_Extractor/Door_14" />
		<exclude body1="Kitchen_Extractor/Door_05" body2="Kitchen_Extractor/Door_13" />
		<exclude body1="Kitchen_Extractor/Door_16" body2="Kitchen_Extractor/Door_11" />
		<exclude body1="Kitchen_Extractor/Door_16" body2="Kitchen_Extractor/Door_10" />
		<exclude body1="Kitchen_Extractor/Door_16" body2="Kitchen_Extractor/Door_07" />
		<exclude body1="Kitchen_Extractor/Door_16" body2="Kitchen_Extractor/Door_09" />
		<exclude body1="Kitchen_Extractor/Door_16" body2="Kitchen_Extractor/Door_08" />
		<exclude body1="Kitchen_Extractor/Door_16" body2="Kitchen_Extractor/Door_06" />
		<exclude body1="Kitchen_Extractor/Door_16" body2="Kitchen_Extractor/Door_01" />
		<exclude body1="Kitchen_Extractor/Door_16" body2="Kitchen_Extractor/Door_12" />
		<exclude body1="Kitchen_Extractor/Door_16" body2="Kitchen_Extractor/Door_15" />
		<exclude body1="Kitchen_Extractor/Door_16" body2="Kitchen_Extractor/Door_14" />
		<exclude body1="Kitchen_Extractor/Door_16" body2="Kitchen_Extractor/Door_13" />
		<exclude body1="Kitchen_Extractor/Door_11" body2="Kitchen_Extractor/Door_10" />
		<exclude body1="Kitchen_Extractor/Door_11" body2="Kitchen_Extractor/Door_07" />
		<exclude body1="Kitchen_Extractor/Door_11" body2="Kitchen_Extractor/Door_09" />
		<exclude body1="Kitchen_Extractor/Door_11" body2="Kitchen_Extractor/Door_08" />
		<exclude body1="Kitchen_Extractor/Door_11" body2="Kitchen_Extractor/Door_06" />
		<exclude body1="Kitchen_Extractor/Door_11" body2="Kitchen_Extractor/Door_01" />
		<exclude body1="Kitchen_Extractor/Door_11" body2="Kitchen_Extractor/Door_12" />
		<exclude body1="Kitchen_Extractor/Door_11" body2="Kitchen_Extractor/Door_15" />
		<exclude body1="Kitchen_Extractor/Door_11" body2="Kitchen_Extractor/Door_14" />
		<exclude body1="Kitchen_Extractor/Door_11" body2="Kitchen_Extractor/Door_13" />
		<exclude body1="Kitchen_Extractor/Door_10" body2="Kitchen_Extractor/Door_07" />
		<exclude body1="Kitchen_Extractor/Door_10" body2="Kitchen_Extractor/Door_09" />
		<exclude body1="Kitchen_Extractor/Door_10" body2="Kitchen_Extractor/Door_08" />
		<exclude body1="Kitchen_Extractor/Door_10" body2="Kitchen_Extractor/Door_06" />
		<exclude body1="Kitchen_Extractor/Door_10" body2="Kitchen_Extractor/Door_01" />
		<exclude body1="Kitchen_Extractor/Door_10" body2="Kitchen_Extractor/Door_12" />
		<exclude body1="Kitchen_Extractor/Door_10" body2="Kitchen_Extractor/Door_15" />
		<exclude body1="Kitchen_Extractor/Door_10" body2="Kitchen_Extractor/Door_14" />
		<exclude body1="Kitchen_Extractor/Door_10" body2="Kitchen_Extractor/Door_13" />
		<exclude body1="Kitchen_Extractor/Door_07" body2="Kitchen_Extractor/Door_09" />
		<exclude body1="Kitchen_Extractor/Door_07" body2="Kitchen_Extractor/Door_08" />
		<exclude body1="Kitchen_Extractor/Door_07" body2="Kitchen_Extractor/Door_06" />
		<exclude body1="Kitchen_Extractor/Door_07" body2="Kitchen_Extractor/Door_01" />
		<exclude body1="Kitchen_Extractor/Door_07" body2="Kitchen_Extractor/Door_12" />
		<exclude body1="Kitchen_Extractor/Door_07" body2="Kitchen_Extractor/Door_15" />
		<exclude body1="Kitchen_Extractor/Door_07" body2="Kitchen_Extractor/Door_14" />
		<exclude body1="Kitchen_Extractor/Door_07" body2="Kitchen_Extractor/Door_13" />
		<exclude body1="Kitchen_Extractor/Door_09" body2="Kitchen_Extractor/Door_08" />
		<exclude body1="Kitchen_Extractor/Door_09" body2="Kitchen_Extractor/Door_06" />
		<exclude body1="Kitchen_Extractor/Door_09" body2="Kitchen_Extractor/Door_01" />
		<exclude body1="Kitchen_Extractor/Door_09" body2="Kitchen_Extractor/Door_12" />
		<exclude body1="Kitchen_Extractor/Door_09" body2="Kitchen_Extractor/Door_15" />
		<exclude body1="Kitchen_Extractor/Door_09" body2="Kitchen_Extractor/Door_14" />
		<exclude body1="Kitchen_Extractor/Door_09" body2="Kitchen_Extractor/Door_13" />
		<exclude body1="Kitchen_Extractor/Door_08" body2="Kitchen_Extractor/Door_06" />
		<exclude body1="Kitchen_Extractor/Door_08" body2="Kitchen_Extractor/Door_01" />
		<exclude body1="Kitchen_Extractor/Door_08" body2="Kitchen_Extractor/Door_12" />
		<exclude body1="Kitchen_Extractor/Door_08" body2="Kitchen_Extractor/Door_15" />
		<exclude body1="Kitchen_Extractor/Door_08" body2="Kitchen_Extractor/Door_14" />
		<exclude body1="Kitchen_Extractor/Door_08" body2="Kitchen_Extractor/Door_13" />
		<exclude body1="Kitchen_Extractor/Door_06" body2="Kitchen_Extractor/Door_01" />
		<exclude body1="Kitchen_Extractor/Door_06" body2="Kitchen_Extractor/Door_12" />
		<exclude body1="Kitchen_Extractor/Door_06" body2="Kitchen_Extractor/Door_15" />
		<exclude body1="Kitchen_Extractor/Door_06" body2="Kitchen_Extractor/Door_14" />
		<exclude body1="Kitchen_Extractor/Door_06" body2="Kitchen_Extractor/Door_13" />
		<exclude body1="Kitchen_Extractor/Door_01" body2="Kitchen_Extractor/Door_12" />
		<exclude body1="Kitchen_Extractor/Door_01" body2="Kitchen_Extractor/Door_15" />
		<exclude body1="Kitchen_Extractor/Door_01" body2="Kitchen_Extractor/Door_14" />
		<exclude body1="Kitchen_Extractor/Door_01" body2="Kitchen_Extractor/Door_13" />
		<exclude body1="Kitchen_Extractor/Door_12" body2="Kitchen_Extractor/Door_15" />
		<exclude body1="Kitchen_Extractor/Door_12" body2="Kitchen_Extractor/Door_14" />
		<exclude body1="Kitchen_Extractor/Door_12" body2="Kitchen_Extractor/Door_13" />
		<exclude body1="Kitchen_Extractor/Door_15" body2="Kitchen_Extractor/Door_14" />
		<exclude body1="Kitchen_Extractor/Door_15" body2="Kitchen_Extractor/Door_13" />
		<exclude body1="Kitchen_Extractor/Door_14" body2="Kitchen_Extractor/Door_13" />
	</contact>
</mujoco>