<mujoco model="MuJoCo Model">
    <compiler angle="radian" autolimits="true"/>
    <default/>

    <asset>
        <texture type="skybox" builtin="gradient" rgb1=".3 .5 .7" rgb2="0 0 0" width="32" height="512"/>
        <texture name="body" type="cube" builtin="flat" mark="cross" width="127" height="1278" rgb1="0.8 0.6 0.4"
                 rgb2="0.8 0.6 0.4" markrgb="1 1 1" random="0.01"/>
        <material name="body" texture="body" texuniform="true" rgba="0.8 0.6 .4 1"/>
        <texture name="grid" type="2d" builtin="checker" width="512" height="512" rgb1=".1 .2 .3" rgb2=".2 .3 .4"/>
        <material name="grid" texture="grid" texrepeat="1 1" texuniform="true" reflectance=".2"/>
    </asset>

    <worldbody>
        <geom name="floor" size="0 0 0.05" type="plane" material="grid" condim="3"/>
        <camera name="fixed" pos="0 -30 30" quat="0.707107 0.707107 0 0"/>
        <light name="top" pos="0 0 1" dir="0 0 -1"/>
        <body name="double_pendulum" pos="0 0 5" gravcomp="0">
            <inertial pos="0 0 0" mass="1" diaginertia="1 1 1"/>
            <joint name="joint_0" pos="0 0 1" axis="1 0 0"/>
            <geom name="link_0" size="0.2 0.2 1" type="box" rgba="1 0 0 1"/>
            <body name="link_1" pos="0 0 -2" gravcomp="0">
                <inertial pos="0 0 0" mass="1" diaginertia="1 1 1"/>
                <joint name="joint_1" pos="0 0 1" axis="1 0 0"/>
                <geom name="link_1_geom" size="0.2 0.2 1" type="box" rgba="0 1 0 1"/>
            </body>
        </body>
    </worldbody>
</mujoco>
