<robot name="fetch">
    <material name="caster_link_material">
        <texture filename="/UrdfBot/Common/M_Slippery.M_Slippery"/>
    </material>

    <link name="base_link">
        <inertial>
            <origin rpy="0 0 0" xyz="-0.00520347 0.000139063 0.185382 "/>
            <mass value="84.80"/>
            <inertia ixx="2.41166" ixy="-2.3669e-06" ixz="-0.000295386" iyy="2.63742" iyz="0.0004154" izz="3.38079"/>
        </inertial>
        <visual>
            <origin rpy="0 0 0" xyz="0 0 0"/>
            <geometry>
                <mesh filename="StaticMesh'/UrdfBot/Fetch_V1/Meshes/base_link.base_link'"/>
            </geometry>
        </visual>
        <collision>
            <origin rpy="0 0 0" xyz="0 0 0"/>
            <geometry>
                <mesh filename="StaticMesh'/UrdfBot/Fetch_V1/Meshes/base_link.base_link'"/>
            </geometry>
        </collision>
    </link>

    <link name="wheel_link_l">
        <inertial>
            <origin rpy="0 0 0" xyz="-5.00679e-08 -0.000628419 -1.17183e-05 "/>
            <mass value="0.928359"/>
            <inertia ixx="0.00133768" ixy="0" ixz="0" iyy="0.00133768" iyz="0" izz="0.00133768"/>
        </inertial>
        <visual>
            <origin rpy="0 0 0" xyz="0 0 0"/>
            <geometry>
                <mesh filename="StaticMesh'/UrdfBot/Fetch_V1/Meshes/wheel_link_l.wheel_link_l'"/>
            </geometry>
        </visual>
        <collision>
            <origin rpy="0 0 0" xyz="0 0 0"/>
            <geometry>
                <mesh filename="StaticMesh'/UrdfBot/Fetch_V1/Meshes/wheel_link_l.wheel_link_l'"/>
            </geometry>
        </collision>
    </link>
    <joint name="wheel_joint_l" type="continuous">
        <origin rpy="0 0 0" xyz="0.0012914 0.18738 0.055325"/>
        <parent link="base_link"/>
        <child link="wheel_link_l"/>
        <axis xyz="0 1 0"/>
        <limit effort="8.85" velocity="17.4"/>
        <dynamics type="velocity" damping="100.0"/>
    </joint>

   <link name="wheel_link_r">
        <inertial>
            <origin rpy="0 0 0" xyz="-5.00679e-08 -0.000628419 -1.17183e-05 "/>
            <mass value="0.928359"/>
            <inertia ixx="0.00133768" ixy="0" ixz="0" iyy="0.00133768" iyz="0" izz="0.00133768"/>
        </inertial>
        <visual>
            <origin rpy="0 0 0" xyz="0 0 0"/>
            <geometry>
                <mesh filename="StaticMesh'/UrdfBot/Fetch_V1/Meshes/wheel_link_r.wheel_link_r'"/>
            </geometry>
        </visual>
        <collision>
            <origin rpy="0 0 0" xyz="0 0 0"/>
            <geometry>
                <mesh filename="StaticMesh'/UrdfBot/Fetch_V1/Meshes/wheel_link_r.wheel_link_r'"/>
            </geometry>
        </collision>
    </link>
    <joint name="wheel_joint_r" type="continuous">
        <origin rpy="0 0 0" xyz="0.0012914 -0.18738 0.055325"/>
        <parent link="base_link"/>
        <child link="wheel_link_r"/>
        <axis xyz="0 1 0"/>
        <limit effort="8.85" velocity="17.4"/>
        <dynamics type="velocity" damping="100.0"/>
    </joint>

    <link name="torso_link">
        <inertial>
            <origin rpy="0 0 0" xyz="-0.0362678 5.31779e-05 0.315626 "/>
            <mass value="19.2258"/>
            <inertia ixx="0.621202" ixy="-1.13186e-06" ixz="-0.0178264" iyy="0.620842" iyz="-4.80704e-05" izz="0.291295"/>
        </inertial>
        <visual>
            <origin rpy="0 0 0" xyz="0 0 0"/>
            <geometry>
                <mesh filename="StaticMesh'/UrdfBot/Fetch_V1/Meshes/torso_link.torso_link'"/>
            </geometry>
        </visual>
        <collision>
            <origin rpy="0 0 0" xyz="0 0 0"/>
            <geometry>
                <mesh filename="StaticMesh'/UrdfBot/Fetch_V1/Meshes/torso_link.torso_link'"/>
            </geometry>
        </collision>
    </link>
    <joint name="torso_joint" type="fixed">
        <origin rpy="0 0 0" xyz="-0.086875 0 0.37743"/>
        <parent link="base_link"/>
        <child link="torso_link"/>
        <axis xyz="0 0 1"/>
        <limit effort="450.0" lower="0" upper="0.38615" velocity="0.1"/>
    </joint>

    <link name="torso_fixed_link">
        <inertial>
            <origin rpy="0 0 0" xyz="-0.0976438 -0.0010593 0.213547 "/>
            <mass value="8.66108"/>
            <inertia ixx="0.209815" ixy="-3.10358e-05" ixz="8.38587e-06" iyy="0.159935" iyz="5.94949e-05" izz="0.0749922"/>
        </inertial>
        <visual>
            <origin rpy="0 0 0" xyz="0 0 0"/>
            <geometry>
                <mesh filename="StaticMesh'/UrdfBot/Fetch_V1/Meshes/torso_fixed_link.torso_fixed_link'"/>
            </geometry>
        </visual>
        <collision>
            <origin rpy="0 0 0" xyz="0 0 0"/>
            <geometry>
                <mesh filename="StaticMesh'/UrdfBot/Fetch_V1/Meshes/torso_fixed_link.torso_fixed_link'"/>
            </geometry>
        </collision>
    </link>
    <joint name="torso_fixed_joint" type="fixed">
        <origin rpy="0 0 0" xyz="-0.086875 0 0.377425"/>
        <parent link="base_link"/>
        <child link="torso_fixed_link"/>
        <axis xyz="0 1 0"/>
    </joint>

    <link name="caster_link_fl">
        <inertial>
            <origin rpy="0 0 0" xyz="0 0 0"/>
            <mass value="0.859567"/>
            <inertia ixx="0.00115663" ixy="0" ixz="0" iyy="0.00115663" iyz="0" izz="0.00115663"/>
        </inertial>
        <visual>
            <origin rpy="0 0 0" xyz="0 0 0"/>
            <geometry>
                <sphere radius="0.058"/> <!-- 0.0601 --> <!-- 0.06033 -->
            </geometry>
            <material name="caster_link_material"/>
        </visual>
        <collision>
            <origin rpy="0 0 0" xyz="0 0 0"/>
            <geometry>
                <sphere radius="0.058"/> <!-- 0.0601 -->
            </geometry>
        </collision>
    </link>
    <joint name="caster_joint_fl" type="fixed">
        <origin rpy="0 0 0" xyz="0.15 0.12 0.055325"/>
        <parent link="base_link"/>
        <child link="caster_link_fl"/>
        <axis xyz="0 1 0"/>
    </joint>

    <link name="caster_link_fr">
        <inertial>
            <origin rpy="0 0 0" xyz="0 0 0"/>
            <mass value="0.859567"/>
            <inertia ixx="0.00115663" ixy="0" ixz="0" iyy="0.00115663" iyz="0" izz="0.00115663"/>
        </inertial>
        <visual>
            <origin rpy="0 0 0" xyz="0 0 0"/>
            <geometry>
                <sphere radius="0.058"/> <!-- 0.0601 --> <!-- 0.06033 -->
            </geometry>
            <material name="caster_link_material"/>
        </visual>
        <collision>
            <origin rpy="0 0 0" xyz="0 0 0"/>
            <geometry>
                <sphere radius="0.058"/> <!-- 0.0601 -->
            </geometry>
        </collision>
    </link>
    <joint name="caster_joint_fr" type="fixed">
        <origin rpy="0 0 0" xyz="0.15 -0.12 0.055325"/>
        <parent link="base_link"/>
        <child link="caster_link_fr"/>
        <axis xyz="0 1 0"/>
    </joint>

    <link name="caster_link_rl">
        <inertial>
            <origin rpy="0 0 0" xyz="0 0 0"/>
            <mass value="0.859567"/>
            <inertia ixx="0.00115663" ixy="0" ixz="0" iyy="0.00115663" iyz="0" izz="0.00115663"/>
        </inertial>
        <visual>
            <origin rpy="0 0 0" xyz="0 0 0"/>
            <geometry>
                <sphere radius="0.058"/> <!-- 0.0601 --> <!-- 0.06033 -->
            </geometry>
            <material name="caster_link_material"/>
        </visual>
        <collision>
            <origin rpy="0 0 0" xyz="0 0 0"/>
            <geometry>
                <sphere radius="0.058"/> <!-- 0.0601 -->
            </geometry>
        </collision>
    </link>
    <joint name="caster_joint_rl" type="fixed">
        <origin rpy="0 0 0" xyz="-0.2 -0.12 0.055325"/>
        <parent link="base_link"/>
        <child link="caster_link_rl"/>
        <axis xyz="0 1 0"/>
    </joint>

    <link name="caster_link_rr">
        <inertial>
            <origin rpy="0 0 0" xyz="0 0 0"/>
            <mass value="0.859567"/>
            <inertia ixx="0.00115663" ixy="0" ixz="0" iyy="0.00115663" iyz="0" izz="0.00115663"/>
        </inertial>
        <visual>
            <origin rpy="0 0 0" xyz="0 0 0"/>
            <geometry>
                <sphere radius="0.058"/> <!-- 0.0601 --> <!-- 0.06033 -->
            </geometry>
            <material name="caster_link_material"/>
        </visual>
        <collision>
            <origin rpy="0 0 0" xyz="0 0 0"/>
            <geometry>
                <sphere radius="0.058"/> <!-- 0.0601 -->
            </geometry>
        </collision>
    </link>
    <joint name="caster_joint_rr" type="fixed">
        <origin rpy="0 0 0" xyz="-0.2 0.12 0.055325"/>
        <parent link="base_link"/>
        <child link="caster_link_rr"/>
        <axis xyz="0 1 0"/>
    </joint>

    <link name="estop_link">
        <inertial>
            <origin rpy="0 0 0" xyz="0.00251956 0.00327102 0.00658276 "/>
            <mass value="0.0968432"/>
            <inertia ixx="2.00292e-05" ixy="-1.67442e-06" ixz="-8.26677e-07" iyy="1.996e-05" iyz="-8.72182e-07" izz="1.79424e-05"/>
        </inertial>
        <visual>
            <origin rpy="0 0 0" xyz="0 0 0"/>
            <geometry>
                <mesh filename="StaticMesh'/UrdfBot/Fetch_V1/Meshes/estop_link.estop_link'"/>
            </geometry>
        </visual>
        <collision>
            <origin rpy="0 0 0" xyz="0 0 0"/>
            <geometry>
                <mesh filename="StaticMesh'/UrdfBot/Fetch_V1/Meshes/estop_link.estop_link'"/>
            </geometry>
        </collision>
    </link>
    <joint name="estop_joint" type="fixed">
        <origin rpy="1.5708 0 0" xyz="-0.12465 0.23892 0.31127"/>
        <parent link="base_link"/>
        <child link="estop_link"/>
        <axis xyz="0 0 0"/>
    </joint>

    <link name="laser_link">
        <inertial>
            <origin rpy="0 0 0" xyz="-0.0322242 -0.000272554 0.055607 "/>
            <mass value="0.047008"/>
            <inertia ixx="8.01191e-06" ixy="3.09727e-08" ixz="-5.97443e-07" iyy="3.71956e-06" iyz="4.8885e-08" izz="9.18039e-06"/>
        </inertial>
        <visual>
            <origin rpy="0 0 0" xyz="0 0 0"/>
            <geometry>
                <mesh filename="StaticMesh'/UrdfBot/Fetch_V1/Meshes/laser_link.laser_link'"/>
            </geometry>
        </visual>
        <collision>
            <origin rpy="0 0 0" xyz="0 0 0"/>
            <geometry>
                <mesh filename="StaticMesh'/UrdfBot/Fetch_V1/Meshes/laser_link.laser_link'"/>
            </geometry>
        </collision>
    </link>
    <joint name="laser_joint" type="fixed">
        <origin rpy="3.14159265359 0 0" xyz="0.235 0 0.2878"/>
        <parent link="base_link"/>
        <child link="laser_link"/>
        <axis xyz="0 0 0"/>
    </joint>

    <link name="arm_link_0">
        <inertial>
            <origin rpy="0 0 0" xyz="0.0597524 0.0115767 0.0306527 "/>
            <mass value="2.42679"/>
            <inertia ixx="0.00721448" ixy="-0.000767278" ixz="-0.00152705" iyy="0.0112945" iyz="-0.000702912" izz="0.00987099"/>
        </inertial>
        <visual>
            <origin rpy="0 0 0" xyz="0 0 0"/>
            <geometry>
                <mesh filename="StaticMesh'/UrdfBot/Fetch_V1/Meshes/arm_link_0.arm_link_0'"/>
            </geometry>
        </visual>
        <collision>
            <origin rpy="0 0 0" xyz="0 0 0"/>
            <geometry>
                <mesh filename="StaticMesh'/UrdfBot/Fetch_V1/Meshes/arm_link_0.arm_link_0'"/>
            </geometry>
        </collision>
    </link>
    <joint name="arm_joint_0" type="revolute">
        <origin rpy="0 0 0" xyz="0.119525 0 0.34858"/>
        <parent link="torso_link"/>
        <child link="arm_link_0"/>
        <axis xyz="0 0 1"/>
        <dynamics type="position" spring="100.0" damping="10.0"/>
        <limit effort="33.82" lower="-1.6056" upper="1.6056" velocity="1.256"/>
    </joint>

    <link name="arm_link_1">
        <inertial>
            <origin rpy="0 0 0" xyz="0.0646285 -0.0148527 -4.10768e-06 "/>
            <mass value="1.92394"/>
            <inertia ixx="0.00350956" ixy="-0.000333891" ixz="4.02615e-07" iyy="0.00872238" iyz="2.2514e-08"
                     izz="0.00921198"/>
        </inertial>
        <visual>
            <origin rpy="0 0 0" xyz="0 0 0"/>
            <geometry>
                <mesh filename="StaticMesh'/UrdfBot/Fetch_V1/Meshes/arm_link_1.arm_link_1'"/>
            </geometry>
        </visual>
        <collision>
            <origin rpy="0 0 0" xyz="0 0 0"/>
            <geometry>
                <mesh filename="StaticMesh'/UrdfBot/Fetch_V1/Meshes/arm_link_1.arm_link_1'"/>
            </geometry>
        </collision>
    </link>
    <joint name="arm_joint_1" type="revolute">
        <origin rpy="0 0 0" xyz="0.117 0 0.06"/>
        <parent link="arm_link_0"/>
        <child link="arm_link_1"/>
        <axis xyz="0 1 0"/>
        <dynamics type="position" spring="100.0" damping="10.0"/>
        <limit effort="131.76" lower="-1.221" upper="1.518" velocity="1.454"/>
    </joint>

    <link name="arm_link_2">
        <inertial>
            <origin rpy="0 0 0" xyz="0.0609468 0.013723 -7.28639e-06 "/>
            <mass value="1.92161"/>
            <inertia ixx="0.00350622" ixy="-0.000346942" ixz="3.67812e-06" iyy="0.00867585" iyz="2.68683e-06" izz="0.00917158"/>
        </inertial>
        <visual>
            <origin rpy="0 0 0" xyz="0 0 0"/>
            <geometry>
                <mesh filename="StaticMesh'/UrdfBot/Fetch_V1/Meshes/arm_link_2.arm_link_2'"/>
            </geometry>
        </visual>
        <collision>
            <origin rpy="0 0 0" xyz="0 0 0"/>
            <geometry>
                <mesh filename="StaticMesh'/UrdfBot/Fetch_V1/Meshes/arm_link_2.arm_link_2'"/>
            </geometry>
        </collision>
    </link>
    <joint name="arm_joint_2" type="continuous">
        <origin rpy="0 0 0" xyz="0.219 0 0"/>
        <parent link="arm_link_1"/>
        <child link="arm_link_2"/>
        <axis xyz="1 0 0"/>
        <dynamics type="position" spring="100.0" damping="10.0"/>
        <limit effort="76.94" velocity="1.571"/>
    </joint>

    <link name="arm_link_3">
        <inertial>
            <origin rpy="0 0 0" xyz="0.0652479 -0.0136339 -3.24867e-06 "/>
            <mass value="1.83165"/>
            <inertia ixx="0.00333264" ixy="-0.000323891" ixz="3.6194e-07" iyy="0.00748062" iyz="3.70184e-08" izz="0.00794602"/>
        </inertial>
        <visual>
            <origin rpy="0 0 0" xyz="0 0 0"/>
            <geometry>
                <mesh filename="StaticMesh'/UrdfBot/Fetch_V1/Meshes/arm_link_3.arm_link_3'"/>
            </geometry>
        </visual>
        <collision>
            <origin rpy="0 0 0" xyz="0 0 0"/>
            <geometry>
                <mesh filename="StaticMesh'/UrdfBot/Fetch_V1/Meshes/arm_link_3.arm_link_3'"/>
            </geometry>
        </collision>
    </link>
    <joint name="arm_joint_3" type="revolute">
        <origin rpy="0 0 0" xyz="0.133 0 0"/>
        <parent link="arm_link_2"/>
        <child link="arm_link_3"/>
        <axis xyz="0 1 0"/>
        <dynamics type="position" spring="50.0" damping="1.0"/>
        <limit effort="66.18" lower="-2.251" upper="2.251" velocity="1.521"/>
    </joint>

    <link name="arm_link_4">
        <inertial>
            <origin rpy="0 0 0" xyz="0.0548723 0.026738 0.000262131 "/>
            <mass value="1.768"/>
            <inertia ixx="0.00373396" ixy="-0.0010542" ixz="6.06092e-06" iyy="0.00607268" iyz="-1.25934e-06" izz="0.00689591"/>
        </inertial>
        <visual>
            <origin rpy="0 0 0" xyz="0 0 0"/>
            <geometry>
                <mesh filename="StaticMesh'/UrdfBot/Fetch_V1/Meshes/arm_link_4.arm_link_4'"/>
            </geometry>
        </visual>
        <collision>
            <origin rpy="0 0 0" xyz="0 0 0"/>
            <geometry>
                <mesh filename="StaticMesh'/UrdfBot/Fetch_V1/Meshes/arm_link_4.arm_link_4'"/>
            </geometry>
        </collision>
    </link>
    <joint name="arm_joint_4" type="continuous">
        <origin rpy="0 0 0" xyz="0.197 0 0"/>
        <parent link="arm_link_3"/>
        <child link="arm_link_4"/>
        <axis xyz="1 0 0"/>
        <dynamics type="position" spring="100.0" damping="10.0"/>
        <limit effort="29.35" velocity="1.571"/>
    </joint>

    <link name="arm_link_5">
        <inertial>
            <origin rpy="0 0 0" xyz="0.0362704 -0.00693841 -9.94034e-06 "/>
            <mass value="1.59275"/>
            <inertia ixx="0.00309028" ixy="-4.40467e-05" ixz="1.02303e-07" iyy="0.00461041" iyz="4.49183e-07" izz="0.00508552"/>
        </inertial>
        <visual>
            <origin rpy="0 0 0" xyz="0 0 0"/>
            <geometry>
                <mesh filename="StaticMesh'/UrdfBot/Fetch_V1/Meshes/arm_link_5.arm_link_5'"/>
            </geometry>
        </visual>
        <collision>
            <origin rpy="0 0 0" xyz="0 0 0"/>
            <geometry>
                <mesh filename="StaticMesh'/UrdfBot/Fetch_V1/Meshes/arm_link_5.arm_link_5'"/>
            </geometry>
        </collision>
    </link>
    <joint name="arm_joint_5" type="revolute">
        <origin rpy="0 0 0" xyz="0.1245 0 0"/>
        <parent link="arm_link_4"/>
        <child link="arm_link_5"/>
        <axis xyz="0 1 0"/>
        <dynamics type="position" spring="100.0" damping="10.0"/>
        <limit effort="25.7" lower="-2.16" upper="2.16" velocity="2.268"/>
    </joint>

    <link name="arm_link_6">
        <inertial>
            <origin rpy="0 0 0" xyz="-0.00329332 -1.90114e-06 2.07067e-06 "/>
            <mass value="0.462784"/>
            <inertia ixx="0.00061494" ixy="-9.76122e-09" ixz="5.31892e-10" iyy="0.000376203" iyz="-2.17401e-09" izz="0.00037614"/>
        </inertial>
        <visual>
            <origin rpy="0 0 0" xyz="0 0 0"/>
            <geometry>
                <mesh filename="StaticMesh'/UrdfBot/Fetch_V1/Meshes/arm_link_6.arm_link_6'"/>
            </geometry>
        </visual>
        <collision>
            <origin rpy="0 0 0" xyz="0 0 0"/>
            <geometry>
                <mesh filename="StaticMesh'/UrdfBot/Fetch_V1/Meshes/arm_link_6.arm_link_6'"/>
            </geometry>
        </collision>
    </link>
    <joint name="arm_joint_6" type="continuous">
        <origin rpy="0 0 0" xyz="0.1385 0 0"/>
        <parent link="arm_link_5"/>
        <child link="arm_link_6"/>
        <axis xyz="1 0 0"/>
        <limit effort="7.36" velocity="2.268"/>
        <dynamics type="position" spring="100.0" damping="10.0"/>
    </joint>

    <link name="gripper_link">
        <inertial>
            <origin rpy="0 0 0" xyz="-0.0935447 1.82109e-07 0.000188893 "/>
            <mass value="1.12951"/>
            <inertia ixx="0.00191702" ixy="1.73381e-08" ixz="3.79994e-08" iyy="0.00202664" iyz="-4.4247e-09" izz="0.00282007"/>
        </inertial>
        <visual>
            <origin rpy="0 0 0" xyz="0 0 0"/>
            <geometry>
                <mesh filename="StaticMesh'/UrdfBot/Fetch_V1/Meshes/gripper_link.gripper_link'"/>
            </geometry>
        </visual>
        <collision>
            <origin rpy="0 0 0" xyz="0 0 0"/>
            <geometry>
                <mesh filename="StaticMesh'/UrdfBot/Fetch_V1/Meshes/gripper_link.gripper_link'"/>
            </geometry>
        </collision>
    </link>
    <joint name="gripper_axis" type="fixed">
        <origin rpy="0 0 0" xyz="0.16645 0 0"/>
        <parent link="arm_link_6"/>
        <child link="gripper_link"/>
        <axis xyz="0 1 0"/>
    </joint>

    <link name="gripper_finger_link_l">
        <inertial>
            <origin rpy="0 0 0" xyz="4.38073e-05 0.108626 0.000716377 "/>
            <mass value="0.0785086"/>
            <inertia ixx="6.98014e-06" ixy="-2.62572e-08" ixz="-1.58206e-08" iyy="4.12665e-05" iyz="-1.57909e-09" izz="3.75763e-05"/>
        </inertial>
        <visual>
            <origin rpy="0 0 0" xyz="0 0.101425 0"/>
            <geometry>
                <mesh filename="StaticMesh'/UrdfBot/Fetch_V1/Meshes/gripper_finger_link_l.gripper_finger_link_l'"/>
            </geometry>
        </visual>
        <collision>
            <origin rpy="0 0 0" xyz="0 0.101425 0"/>
            <geometry>
                <mesh filename="StaticMesh'/UrdfBot/Fetch_V1/Meshes/gripper_finger_link_l.gripper_finger_link_l'"/>
            </geometry>
        </collision>
    </link>
    <joint name="gripper_finger_joint_l" type="prismatic">
        <origin rpy="0 0 0" xyz="0 0 0"/>
        <parent link="gripper_link"/>
        <child link="gripper_finger_link_l"/>
        <axis xyz="0 -1 0"/>
        <limit effort="60" lower="0.0" upper="0.05" velocity="0.05"/>
        <dynamics type="torque" spring="0" damping="0"/>
    </joint>

    <link name="gripper_finger_link_r">
        <inertial>
            <origin rpy="0 0 0" xyz="0 -0.108614 -4.88408e-06 "/>
            <mass value="0.0744093"/>
            <inertia ixx="6.15416e-06" ixy="-1.5025e-09" ixz="0" iyy="3.87474e-05" iyz="0" izz="3.55162e-05"/>
        </inertial>
        <visual>
            <origin rpy="0 0 0" xyz="0 -0.101425 0"/>
            <geometry>
                <mesh filename="StaticMesh'/UrdfBot/Fetch_V1/Meshes/gripper_finger_link_r.gripper_finger_link_r'"/>
            </geometry>
        </visual>
        <collision>
            <origin rpy="0 0 0" xyz="0 -0.101425 0"/>
            <geometry>
                <mesh filename="StaticMesh'/UrdfBot/Fetch_V1/Meshes/gripper_finger_link_r.gripper_finger_link_r'"/>
            </geometry>
        </collision>
    </link>
    <joint name="gripper_finger_joint_r" type="prismatic">
        <origin rpy="0 0 0" xyz="0 0 0"/>
        <parent link="gripper_link"/>
        <child link="gripper_finger_link_r"/>
        <axis xyz="0 1 0"/>
        <limit effort="60" lower="0.0" upper="0.05" velocity="0.05"/>
        <dynamics type="torque" spring="0" damping="0"/>
    </joint>

    <link name="head_pan_link">
        <inertial>
            <origin rpy="0 0 0" xyz="0.052108 -1.05103e-08 0.0566172 "/>
            <mass value="4.92362"/>
            <inertia ixx="0.0340263" ixy="-4.31717e-10" ixz="-0.000736158" iyy="0.0365178" iyz="6.67932e-11" izz="0.0607599"/>
        </inertial>
        <visual>
            <origin rpy="0 0 0" xyz="0 0 0"/>
            <geometry>
                <mesh filename="StaticMesh'/UrdfBot/Fetch_V1/Meshes/head_pan_link.head_pan_link'"/>
            </geometry>
        </visual>
        <collision>
            <origin rpy="0 0 0" xyz="0 0 0"/>
            <geometry>
                <mesh filename="StaticMesh'/UrdfBot/Fetch_V1/Meshes/head_pan_link_collision.head_pan_link_collision'"/>
            </geometry>
        </collision>
    </link>
    <joint name="head_pan_joint" type="revolute">
        <origin rpy="0 0 0" xyz="0.053125 0 0.603001417713939"/>
        <parent link="torso_link"/>
        <child link="head_pan_link"/>
        <axis xyz="0 0 1"/>
        <dynamics type="position" spring="10.0" damping="1.0"/>
        <limit effort="0.32" lower="-1.57" upper="1.57" velocity="1.57"/>
    </joint>

    <link name="head_tilt_link">
        <inertial>
            <origin rpy="0 0 0" xyz="0.00225553 -0.000111501 0.00229468 "/>
            <mass value="1.7198"/>
            <inertia ixx="0.00763106" ixy="1.8476e-06" ixz="-0.000150895" iyy="0.00275096" iyz="-1.05117e-06"
                     izz="0.00762932"/>
        </inertial>
        <visual>
            <origin rpy="0 0 0" xyz="0 0 0"/>
            <geometry>
                <mesh filename="StaticMesh'/UrdfBot/Fetch_V1/Meshes/head_tilt_link.head_tilt_link'"/>
            </geometry>
        </visual>
        <collision>
            <origin rpy="0 0 0" xyz="0 0 0"/>
            <geometry>
                <mesh filename="StaticMesh'/UrdfBot/Fetch_V1/Meshes/head_tilt_link_collision.head_tilt_link_collision'"/>
            </geometry>
        </collision>
    </link>
    <joint name="head_tilt_joint" type="revolute">
        <origin rpy="0 0 0" xyz="0.14253 0 0.057999"/>
        <parent link="head_pan_link"/>
        <child link="head_tilt_link"/>
        <axis xyz="0 1 0"/>
        <dynamics type="position" spring="10.0" damping="1.0"/>
        <limit effort="0.68" lower="-0.76" upper="1.45" velocity="1.57"/>
    </joint>

</robot>
