<?xml version="1.0" ?>
<robot name="locobot">

    <link name="base_link">
        <visual>
            <geometry>
                <mesh filename="/UrdfBot/LocoBot_V0/Meshes/main_body.main_body"/>
                <!--                <cylinder length="0.05" radius="0.178"/>-->
            </geometry>
            <origin rpy="0 0 0" xyz="0 0 0"/>
        </visual>
        <collision name="base">
            <geometry>
                <mesh filename="/UrdfBot/LocoBot_V0/Meshes/main_body.main_body"/>
                <!--                <cylinder length="0.05" radius="0.178"/>-->
            </geometry>
            <origin rpy="0 0 0" xyz="0 0 0"/>
        </collision>
        <inertial>
            <!-- COM experimentally determined -->
            <origin xyz="0.01 0 0"/>
            <mass value="2.4"/>
            <!-- 2.4/2.6 kg for small/big battery pack -->
            <!-- Kobukis inertia tensor is approximated by a cylinder with homogeneous mass distribution
             More details: http://en.wikipedia.org/wiki/List_of_moment_of_inertia_tensors
             m = 2.4 kg; h = 0.09 m; r = 0.175 m
             ixx = 1/12 * m * (3 * r^2 + h^2)
             iyy = 1/12 * m * (3 * r^2 + h^2)
             izz = 1/2 * m * r^2
          -->
            <inertia ixx="0.019995" ixy="0.0" ixz="0.0" iyy="0.019995" iyz="0.0" izz="0.03675"/>
        </inertial>
    </link>
    <joint name="wheel_left_joint" type="continuous">
        <parent link="base_link"/>
        <child link="wheel_left_link"/>
        <origin rpy="-1.57079632679 0 0" xyz="0.00 0.115 0.0250"/>
        <axis xyz="0 1 0"/>
        <limit effort="8.85" velocity="17.4"/>
    </joint>
    <link name="wheel_left_link">
        <visual>
            <geometry>
<!--                <mesh filename="/UrdfBot/LocoBot_V0/Meshes/main_wheel.main_wheel"/>-->
                <sphere length="0.0206" radius="0.0350"/>
            </geometry>
            <origin rpy="0 0 0" xyz="0 0 0"/>
        </visual>
        <collision>
            <geometry>
<!--                <mesh filename="/UrdfBot/LocoBot_V0/Meshes/main_wheel.main_wheel"/>-->
                <sphere length="0.0206" radius="0.0350"/>
            </geometry>
            <origin rpy="0 0 0" xyz="0 0 0"/>
        </collision>
        <inertial>
            <mass value="1"/>
            <origin xyz="0 0 0"/>
            <inertia ixx="0.001" ixy="0.0" ixz="0.0" iyy="0.001" iyz="0.0" izz="0.001"/>
        </inertial>
    </link>
    <joint name="wheel_right_joint" type="continuous">
        <parent link="base_link"/>
        <child link="wheel_right_link"/>
        <origin rpy="-1.57079632679 0 0" xyz="0.00 -0.115 0.0250"/>
        <axis xyz="0 1 0"/>
        <limit effort="8.85" velocity="17.4"/>
    </joint>
    <link name="wheel_right_link">
        <visual>
            <geometry>
<!--                <mesh filename="/UrdfBot/LocoBot_V0/Meshes/main_wheel.main_wheel"/>-->
                <sphere length="0.0206" radius="0.0350"/>
            </geometry>
            <origin rpy="0 0 0" xyz="0 0 0"/>
        </visual>
        <collision>
            <geometry>
<!--                <mesh filename="/UrdfBot/LocoBot_V0/Meshes/main_wheel.main_wheel"/>-->
                <sphere length="0.0206" radius="0.0350"/>
            </geometry>
            <origin rpy="0 0 0" xyz="0 0 0"/>
        </collision>
        <inertial>
            <mass value="1"/>
            <origin xyz="0 0 0"/>
            <inertia ixx="0.001" ixy="0.0" ixz="0.0" iyy="0.001" iyz="0.0" izz="0.001"/>
        </inertial>
    </link>
    <joint name="caster_front_joint" type="fixed">
        <parent link="base_link"/>
        <child link="caster_front_link"/>
        <origin rpy="-1.57079632679 0 0" xyz="0.115 0.0 0.0260"/>
    </joint>
    <link name="caster_front_link">
        <visual>
            <geometry>
                <sphere length="0.0206" radius="0.0350"/>
            </geometry>
            <origin rpy="0 0 0" xyz="0 0 0"/>
            <material name="caster_link_material">
                <texture filename="/UrdfBot/Common/M_Slippery.M_Slippery"/>
            </material>
        </visual>
        <collision>
            <geometry>
                <sphere length="0.0206" radius="0.0350"/>
            </geometry>
            <origin rpy="0 0 0" xyz="0 0 0"/>
        </collision>
        <inertial>
            <mass value="1"/>
            <origin xyz="0 0 0"/>
            <inertia ixx="0.001" ixy="0.0" ixz="0.0" iyy="0.001" iyz="0.0" izz="0.001"/>
        </inertial>
    </link>
    <joint name="caster_back_joint" type="fixed">
        <parent link="base_link"/>
        <child link="caster_back_link"/>
        <origin rpy="-1.57079632679 0 0" xyz="-0.135 0.0 0.025"/>
    </joint>
    <link name="caster_back_link">
        <visual>
            <geometry>
                <sphere length="0.0206" radius="0.0350"/>
            </geometry>
            <origin rpy="0 0 0" xyz="0 0 0"/>
            <material name="caster_link_material">
                <texture filename="/UrdfBot/Common/M_Slippery.M_Slippery"/>
            </material>
        </visual>
        <collision>
            <geometry>
                <sphere length="0.0206" radius="0.0350"/>
            </geometry>
            <origin rpy="0 0 0" xyz="0 0 0"/>
        </collision>
        <inertial>
            <mass value="1"/>
            <origin xyz="0 0 0"/>
            <inertia ixx="0.001" ixy="0.0" ixz="0.0" iyy="0.001" iyz="0.0" izz="0.001"/>
        </inertial>
    </link>

    <!-- plates  -->
    <link name="plate_1">
        <inertial>
            <origin rpy="0 0 0" xyz="0 0 0"/>
            <mass value="0.640128902693298"/>
            <inertia ixx="0.0212697824374231" ixy="-1.84819421839641E-07" ixz="0.00177278831625861" iyy="0.0200161122874848" iyz="1.82514218153984E-07" izz="0.00538401325307411"/>
        </inertial>
        <visual>
            <origin rpy="0 0 0" xyz="0 0 0"/>
            <geometry>
                <mesh filename="/UrdfBot/LocoBot_V0/Meshes/plate.plate"/>
            </geometry>
<!--            <material name="">-->
<!--                <color rgba="0.792156862745098 0.819607843137255 0.933333333333333 1"/>-->
<!--            </material>-->
        </visual>
        <collision>
            <origin rpy="0 0 0" xyz="0 0 0"/>
            <geometry>
                <mesh filename="/UrdfBot/LocoBot_V0/Meshes/plate.plate"/>
            </geometry>
        </collision>
    </link>
    <joint name="plate_1_joint" type="fixed">
        <origin rpy="0 0 0" xyz="0.0973 0 0.0902375"/>
        <parent link="base_link"/>
        <child link="plate_1"/>
        <axis xyz="0 0 0"/>
    </joint>
    <link name="plate_2">
        <inertial>
            <origin rpy="0 0 0" xyz="0 0 0"/>
            <mass value="0.640128902693298"/>
            <inertia ixx="0.0212697824374231" ixy="-1.84819421839641E-07" ixz="0.00177278831625861" iyy="0.0200161122874848" iyz="1.82514218153984E-07" izz="0.00538401325307411"/>
        </inertial>
        <visual>
            <origin rpy="0 0 0" xyz="0 0 0"/>
            <geometry>
                <mesh filename="/UrdfBot/LocoBot_V0/Meshes/plate.plate"/>
            </geometry>
<!--            <material name="">-->
<!--                <color rgba="0.792156862745098 0.819607843137255 0.933333333333333 1"/>-->
<!--            </material>-->
        </visual>
        <collision>
            <origin rpy="0 0 0" xyz="0 0 0"/>
            <geometry>
                <mesh filename="/UrdfBot/LocoBot_V0/Meshes/plate.plate"/>
            </geometry>
        </collision>
    </link>
    <joint name="plate_2_joint" type="fixed">
        <origin rpy="0 0 0" xyz="0 0 0.0047625"/>
        <parent link="plate_1"/>
        <child link="plate_2"/>
        <axis xyz="0 0 0"/>
    </joint>
    <!-- add arm -->
    <link name="arm_base_link">
        <inertial>
            <origin rpy="0 0 0" xyz="-1.86027246940057E-08 -1.84987775462994E-08 0.0400356424684456"/>
            <mass value="0.531491686912019"/>
            <inertia ixx="0.000533657400855491" ixy="-4.44205269454465E-09" ixz="2.11078566024265E-10" iyy="0.000533665698902565" iyz="5.02029005902419E-11" izz="0.00071572082392375"/>
        </inertial>
        <visual>
            <origin rpy="0 0 0" xyz="0 0 0"/>
            <geometry>
                <mesh filename="/UrdfBot/LocoBot_V0/Meshes/arm_base_link.arm_base_link"/>
            </geometry>
<!--            <material name="">-->
<!--                <color rgba="0.792156862745098 0.819607843137255 0.933333333333333 1"/>-->
<!--            </material>-->
        </visual>
        <collision>
            <origin rpy="0 0 0" xyz="0 0 0"/>
            <geometry>
                <mesh filename="/UrdfBot/LocoBot_V0/Meshes/arm_base_link.arm_base_link"/>
            </geometry>
        </collision>
    </link>
    <joint name="arm_base_link_joint" type="fixed">
        <origin rpy="0 0 0" xyz="0 0 0.001"/>
        <parent link="plate_2"/>
        <child link="arm_base_link"/>
        <axis xyz="0 0 0"/>
    </joint>
    <link name="shoulder_link">
        <inertial>
            <origin rpy="0 0 0" xyz="-5.67968980068612E-05 1.09785478984274E-10 0.0228467386735302"/>
            <mass value="0.119861197293521"/>
            <inertia ixx="0.000161288180462291" ixy="7.59806211309873E-14" ixz="-1.45323090659527E-07" iyy="5.49696562437107E-05" iyz="1.81052501311883E-13" izz="0.000150800672543169"/>
        </inertial>
        <visual>
            <origin rpy="0 0 0" xyz="0 0 0"/>
            <geometry>
                <mesh filename="/UrdfBot/LocoBot_V0/Meshes/shoulder_link.shoulder_link"/>
            </geometry>
<!--            <material name="">-->
<!--                <color rgba="0.792156862745098 0.819607843137255 0.933333333333333 1"/>-->
<!--            </material>-->
        </visual>
        <collision>
            <origin rpy="0 0 0" xyz="0 0 0"/>
            <geometry>
                <mesh filename="/UrdfBot/LocoBot_V0/Meshes/shoulder_link.shoulder_link"/>
            </geometry>
        </collision>
    </link>
    <joint name="joint_1" type="revolute">
        <origin rpy="0 0 0" xyz="0 0 0.072"/>
        <parent link="arm_base_link"/>
        <child link="shoulder_link"/>
        <axis xyz="0 0 1"/>
        <limit effort="10" lower="-1.57" upper="1.57" velocity="1"/>
    </joint>
    <link name="elbow_link">
        <inertial>
            <origin rpy="0 0 0" xyz="0.00959755948481227 -2.30930057287648E-10 0.134296795349987"/>
            <mass value="0.212482745791037"/>
            <inertia ixx="0.0011748973771367" ixy="-4.7094567420817E-13" ixz="-0.000132188939134774" iyy="0.00122350302249847" iyz="-5.48932537472287E-12" izz="9.02202689343621E-05"/>
        </inertial>
        <visual>
            <origin rpy="0 0 0" xyz="0 0 0"/>
            <geometry>
                <mesh filename="/UrdfBot/LocoBot_V0/Meshes/elbow_link.elbow_link"/>
            </geometry>
<!--            <material name="">-->
<!--                <color rgba="0.792156862745098 0.819607843137255 0.933333333333333 1"/>-->
<!--            </material>-->
        </visual>
        <collision>
            <origin rpy="0 0 0" xyz="0 0 0"/>
            <geometry>
                <mesh filename="/UrdfBot/LocoBot_V0/Meshes/elbow_link.elbow_link"/>
            </geometry>
        </collision>
    </link>
    <joint name="joint_2" type="revolute">
        <origin rpy="0 0 0" xyz="0 0 0.04125"/>
        <parent link="shoulder_link"/>
        <child link="elbow_link"/>
        <axis xyz="0 1 0"/>
        <limit effort="10" lower="-1.57" upper="1.57" velocity="1"/>
    </joint>
    <link name="forearm_link">
        <inertial>
            <origin rpy="0 0 0" xyz="0.117829826272582 3.09310973110905E-15 -1.26218883678142E-08"/>
            <mass value="0.18746427435805"/>
            <inertia ixx="3.94142667601686E-05" ixy="-3.65830967659785E-19" ixz="9.25852572167442E-11" iyy="0.000725209569605637" iyz="-1.05290858715495E-18" izz="0.000737165881391993"/>
        </inertial>
        <visual>
            <origin rpy="0 0 0" xyz="0 0 0"/>
            <geometry>
                <mesh filename="/UrdfBot/LocoBot_V0/Meshes/forearm_link.forearm_link"/>
            </geometry>
<!--            <material name="">-->
<!--                <color rgba="0.792156862745098 0.819607843137255 0.933333333333333 1"/>-->
<!--            </material>-->
        </visual>
        <collision>
            <origin rpy="0 0 0" xyz="0 0 0"/>
            <geometry>
                <mesh filename="/UrdfBot/LocoBot_V0/Meshes/forearm_link.forearm_link"/>
            </geometry>
        </collision>
    </link>
    <joint name="joint_3" type="revolute">
        <origin rpy="0 0 0" xyz="0.05 0 0.2"/>
        <parent link="elbow_link"/>
        <child link="forearm_link"/>
        <axis xyz="0 1 0"/>
        <limit effort="10" lower="-1.57" upper="1.57" velocity="1"/>
    </joint>
    <link name="wrist_link">
        <inertial>
            <origin rpy="0 0 0" xyz="0.0429410028407894 4.98644733821042E-05 0.0114266948023652"/>
            <mass value="0.0605921736680362"/>
            <inertia ixx="1.84998512056284E-05" ixy="-1.03256667343112E-08" ixz="-1.71865409274096E-06" iyy="2.08955068262134E-05" iyz="5.05203399787143E-09" izz="1.97857037442992E-05"/>
        </inertial>
        <visual>
            <origin rpy="0 0 0" xyz="0 0 0"/>
            <geometry>
                <mesh filename="/UrdfBot/LocoBot_V0/Meshes/wrist_link.wrist_link"/>
            </geometry>
<!--            <material name="">-->
<!--                <color rgba="0.792156862745098 0.819607843137255 0.933333333333333 1"/>-->
<!--            </material>-->
        </visual>
        <collision>
            <origin rpy="0 0 0" xyz="0 0 0"/>
            <geometry>
                <mesh filename="/UrdfBot/LocoBot_V0/Meshes/wrist_link.wrist_link"/>
            </geometry>
        </collision>
    </link>
    <joint name="joint_4" type="revolute">
        <origin rpy="0 0 0" xyz="0.2002 0 0"/>
        <parent link="forearm_link"/>
        <child link="wrist_link"/>
        <axis xyz="0 1 0"/>
        <limit effort="1" lower="-1.57" upper="1.57" velocity="1"/>
    </joint>
    <link name="gripper_link">
        <inertial>
            <origin rpy="0 0 0" xyz="0.0311572802112565 -1.25977280754998E-05 0.0092307003092138"/>
            <mass value="0.0795745052466434"/>
            <inertia ixx="3.27413333929741E-05" ixy="3.7314060486416E-08" ixz="3.97669066588691E-06" iyy="4.47182985231326E-05" iyz="-9.49992756213297E-09" izz="5.02142570756738E-05"/>
        </inertial>
        <visual>
            <origin rpy="0 0 0" xyz="0 0 0"/>
            <geometry>
                <mesh filename="/UrdfBot/LocoBot_V0/Meshes/gripper_link.gripper_link"/>
            </geometry>
<!--            <material name="">-->
<!--                <color rgba="0.792156862745098 0.819607843137255 0.933333333333333 1"/>-->
<!--            </material>-->
        </visual>
        <collision>
            <origin rpy="0 0 0" xyz="0 0 0"/>
            <geometry>
                <mesh filename="/UrdfBot/LocoBot_V0/Meshes/gripper_link.gripper_link"/>
            </geometry>
        </collision>
    </link>
    <joint name="joint_5" type="revolute">
        <origin rpy="0 0 0" xyz="0.063 0.0001 0"/>
        <parent link="wrist_link"/>
        <child link="gripper_link"/>
        <axis xyz="-1 0 0"/>
        <limit effort="1" lower="-1.57" upper="1.57" velocity="1"/>
    </joint>
    <link name="finger_r">
        <inertial>
            <origin rpy="0 0 0" xyz="0.0100191457715113 -0.00843835347348892 -0.00483280251641866"/>
            <mass value="0.0121931459003602"/>
            <inertia ixx="6.74016278931418E-07" ixy="-2.36459038775023E-07" ixz="3.1480125304693E-09" iyy="3.10966297287339E-06" iyz="1.19271018871704E-10" izz="2.77935600332309E-06"/>
        </inertial>
        <visual>
            <origin rpy="0 0 0" xyz="0 0 0"/>
            <geometry>
                <mesh filename="/UrdfBot/LocoBot_V0/Meshes/finger_l.finger_l"/>
            </geometry>
        </visual>
        <collision>
            <origin rpy="0 0 0" xyz="0 0 0"/>
            <geometry>
                <mesh filename="/UrdfBot/LocoBot_V0/Meshes/finger_l.finger_l"/>
            </geometry>
        </collision>
    </link>
    <joint name="joint_6" type="prismatic">
        <origin rpy="0 0 0" xyz="0.07285 0 0.0050143"/>
        <parent link="gripper_link"/>
        <child link="finger_r"/>
        <axis xyz="0 -1 0"/>
        <limit effort="1" lower="0" upper="0.04" velocity="1"/>
    </joint>
    <link name="finger_l">
        <inertial>
            <origin rpy="0 0 0" xyz="0.0100191599590265 0.00643833435729511 -0.00483280251641866"/>
            <mass value="0.0121931459003603"/>
            <inertia ixx="6.74017180959932E-07" ixy="2.3646368440071E-07" ixz="3.14801230297432E-09" iyy="3.10966207084492E-06" iyz="-1.19277023229564E-10" izz="2.77935600332313E-06"/>
        </inertial>
        <visual>
            <origin rpy="0 0 0" xyz="0 0 0"/>
            <geometry>
                <mesh filename="/UrdfBot/LocoBot_V0/Meshes/finger_r.finger_r"/>
            </geometry>
        </visual>
        <collision>
            <origin rpy="0 0 0" xyz="0 0 0"/>
            <geometry>
                <mesh filename="/UrdfBot/LocoBot_V0/Meshes/finger_r.finger_r"/>
            </geometry>
        </collision>
    </link>
    <joint name="joint_7" type="prismatic">
        <origin rpy="0 0 0" xyz="0.07285 0 0.0050143"/>
        <parent link="gripper_link"/>
        <child link="finger_l"/>
        <axis xyz="0 1 0"/>
        <limit effort="1" lower="0" upper="0.04" velocity="1"/>
    </joint>
    <link name="ar_tag">
        <inertial>
            <origin rpy="0 0 0" xyz="-1.59182528269852E-09 1.70641183422241E-09 -0.00509579048106218"/>
            <mass value="0.0202622634619862"/>
            <inertia ixx="4.71058333074219E-06" ixy="3.03778067070489E-12" ixz="6.65421687578365E-13" iyy="4.05773489073818E-06" iyz="1.37033485576347E-13" izz="7.92378853658606E-06"/>
        </inertial>
        <visual>
            <origin rpy="0 0 0" xyz="0 0 0"/>
            <geometry>
                <mesh filename="/UrdfBot/LocoBot_V0/Meshes/ar_tag.ar_tag"/>
            </geometry>
<!--            <material name="">-->
<!--                <color rgba="0.792156862745098 0.819607843137255 0.933333333333333 1"/>-->
<!--            </material>-->
        </visual>
        <collision>
            <origin rpy="0 0 0" xyz="0 0 0"/>
            <geometry>
                <mesh filename="/UrdfBot/LocoBot_V0/Meshes/ar_tag.ar_tag"/>
            </geometry>
        </collision>
    </link>
    <joint name="ar_tag_joint" type="fixed">
        <origin rpy="0 0 0" xyz="0.0269499999999999 0 0.04315"/>
        <parent link="gripper_link"/>
        <child link="ar_tag"/>
        <axis xyz="0 0 0"/>
    </joint>
    <!-- need to add camera assembly -->
    <link name="cam_mount">
        <inertial>
            <origin rpy="0 0 0" xyz="0.00357169217419921 -0.000144750803528887 0.178406861295468"/>
            <mass value="0.508068698311304"/>
            <inertia ixx="0.0159487749924762" ixy="9.45818767875249E-08" ixz="-0.000266253609478166" iyy="0.0137751425461872" iyz="2.26699147122113E-06" izz="0.00331206257835318"/>
        </inertial>
        <visual>
            <origin rpy="0 0 0" xyz="0 0 0"/>
            <geometry>
                <mesh filename="/UrdfBot/LocoBot_V0/Meshes/cam_mount.cam_mount"/>
            </geometry>
<!--            <material name="">-->
<!--                <color rgba="0.792156862745098 0.819607843137255 0.933333333333333 1"/>-->
<!--            </material>-->
        </visual>
        <collision>
            <origin rpy="0 0 0" xyz="0 0 0"/>
            <geometry>
                <mesh filename="/UrdfBot/LocoBot_V0/Meshes/cam_mount.cam_mount"/>
            </geometry>
        </collision>
    </link>
    <joint name="cam_mount_joint" type="fixed">
        <origin rpy="0 0 0" xyz="-0.03751 0 0.1331"/>
        <parent link="base_link"/>
        <child link="cam_mount"/>
        <axis xyz="0 0 0"/>
    </joint>
    <link name="head_pan_link">
        <inertial>
            <origin rpy="0 0 0" xyz="-1.35308431126191E-16 -2.97071395261028E-17 0.0220876265081744"/>
            <mass value="0.0182769203076134"/>
            <inertia ixx="1.32243845065555E-05" ixy="5.07660179129181E-13" ixz="1.067515220067E-20" iyy="7.13386116649085E-06" iyz="-1.32882457845217E-20" izz="7.83291781352837E-06"/>
        </inertial>
        <visual>
            <origin rpy="0 0 0" xyz="0 0 0"/>
            <geometry>
                <mesh filename="/UrdfBot/LocoBot_V0/Meshes/tilt_link.tilt_link"/>
            </geometry>
<!--            <material name="">-->
<!--                <color rgba="0.250980392156863 0.250980392156863 0.250980392156863 1"/>-->
<!--            </material>-->
        </visual>
        <collision>
            <origin rpy="0 0 0" xyz="0 0 0"/>
            <geometry>
                <mesh filename="/UrdfBot/LocoBot_V0/Meshes/tilt_link.tilt_link"/>
            </geometry>
        </collision>
    </link>
    <joint name="head_pan_joint" type="revolute">
        <origin rpy="0 0 0" xyz="0.0240154841629213 -0.000373468229198185 0.4065"/>
        <parent link="cam_mount"/>
        <child link="head_pan_link"/>
        <axis xyz="0 0 1"/>
        <limit effort="1" lower="-1.57" upper="1.57" velocity="1"/>
    </joint>
    <link name="head_tilt_link">
        <inertial>
            <origin rpy="0 0 0" xyz="0.0168744200088311 -0.000442984145897884 -0.00405256422002387"/>
            <mass value="0.0547677687275323"/>
            <inertia ixx="1.07071738005716E-05" ixy="-1.46854788384565E-07" ixz="5.59529059364376E-08" iyy="1.77011620295824E-05" iyz="1.27587154712834E-09" izz="2.01583693170578E-05"/>
        </inertial>
        <visual>
            <origin rpy="0 0 0" xyz="0 0 0"/>
            <geometry>
                <mesh filename="/UrdfBot/LocoBot_V0/Meshes/roll_link.roll_link"/>
            </geometry>
<!--            <material name="">-->
<!--                <color rgba="0.792156862745098 0.819607843137255 0.933333333333333 1"/>-->
<!--            </material>-->
        </visual>
        <collision>
            <origin rpy="0 0 0" xyz="0 0 0"/>
            <geometry>
                <mesh filename="/UrdfBot/LocoBot_V0/Meshes/roll_link.roll_link"/>
            </geometry>
        </collision>
    </link>
    <joint name="head_tilt_joint" type="revolute">
        <origin rpy="0 0 0" xyz="0 0 0.05"/>
        <parent link="head_pan_link"/>
        <child link="head_tilt_link"/>
        <axis xyz="0 1 0"/>
        <limit effort="1" lower="-1.57" upper="1.57" velocity="1"/>
    </joint>
    <link name="camera_link">
        <inertial>
            <origin rpy="0 0 0" xyz="-0.0132722976093535 0.00168171470080143 2.49829664994428E-06"/>
            <mass value="0.0381925651163644"/>
            <inertia ixx="2.4688255642946E-05" ixy="1.60697655569215E-07" ixz="1.2993241737711E-08" iyy="3.66669176935806E-06" iyz="1.30215657011203E-08" izz="2.48602467766615E-05"/>
        </inertial>
        <visual>
            <origin rpy="0 0 0" xyz="0 0 0"/>
            <geometry>
                <mesh filename="/UrdfBot/LocoBot_V0/Meshes/camera_link.camera_link"/>
            </geometry>
<!--            <material name="">-->
<!--                <color rgba="0.792156862745098 0.819607843137255 0.933333333333333 1"/>-->
<!--            </material>-->
        </visual>
        <collision>
            <origin rpy="0 0 0" xyz="0 0 0"/>
            <geometry>
                <mesh filename="/UrdfBot/LocoBot_V0/Meshes/camera_link.camera_link"/>
            </geometry>
        </collision>
    </link>
    <joint name="camera_joint" type="fixed">
        <origin rpy="0 0 0" xyz="0.06705 0 -0.00425"/>
        <parent link="head_tilt_link"/>
        <child link="camera_link"/>
        <axis xyz="0 0 0"/>
    </joint>
</robot>
