<mujoco>
	<asset>
		<include file="output/Unknown/Kitchen_Sink/Door_01/cvx/Door_01_assets.xml" />
		<include file="output/Unknown/Kitchen_Sink/Door_06/cvx/Door_06_assets.xml" />
		<include file="output/Unknown/Kitchen_Sink/Door_08/cvx/Door_08_assets.xml" />
		<include file="output/Unknown/Kitchen_Sink/Drawer_02/cvx/Drawer_02_assets.xml" />
		<include file="output/Unknown/Kitchen_Sink/Door_07/cvx/Door_07_assets.xml" />
		<include file="output/Unknown/Kitchen_Sink/Drawer_04/cvx/Drawer_04_assets.xml" />
		<include file="output/Unknown/Kitchen_Sink/Drawer_03/cvx/Drawer_03_assets.xml" />
		<include file="output/Unknown/Kitchen_Sink/Kitchen_Sink_Base/cvx/Kitchen_Sink_Base_assets.xml" />
		<include file="output/Unknown/Kitchen_Sink/Drawer_01/cvx/Drawer_01_assets.xml" />
		<include file="output/Unknown/Kitchen_Sink/Door_05/cvx/Door_05_assets.xml" />
		<include file="output/Unknown/Kitchen_Sink/Door_02/cvx/Door_02_assets.xml" />
		<include file="output/Unknown/Kitchen_Sink/Door_03/cvx/Door_03_assets.xml" />
		<include file="output/Unknown/Kitchen_Sink/Door_04/cvx/Door_04_assets.xml" />
	</asset>
	<worldbody>
		<body name="Kitchen_Sink" pos="-3.081453 -2.507587 0.267545" quat="0.000000 -0.000000 -0.000000 -1.000000">
			<body name="Kitchen_Sink/Door_01" pos="0.638378 -2.199623 0.413661" quat="1.000000 0.000000 0.000000 0.000000">
				<joint name="Kitchen_Sink/PhysicsConstraint_door_01_x_revolute" type="hinge" pos="0.00000 0.00000 0.00000" axis="-0.00000 0.00000 -1.00000" range="-0.08727 1.48353" />
				<include file="output/Unknown/Kitchen_Sink/Door_01/cvx/Door_01_body.xml" />
			</body>
			<body name="Kitchen_Sink/Door_06" pos="0.638378 0.527167 0.357177" quat="1.000000 0.000000 0.000000 0.000000">
				<joint name="Kitchen_Sink/PhysicsConstraint_door_06_x_revolute" type="hinge" pos="0.00000 0.00000 0.00000" axis="-0.00000 -0.00000 -1.00000" range="-1.48353 0.08727" />
				<include file="output/Unknown/Kitchen_Sink/Door_06/cvx/Door_06_body.xml" />
			</body>
			<body name="Kitchen_Sink/Door_08" pos="0.638378 1.368899 0.490345" quat="1.000000 0.000000 0.000000 0.000000">
				<joint name="Kitchen_Sink/PhysicsConstraint_door_08_x_revolute" type="hinge" pos="0.00000 0.00000 0.00000" axis="-0.00000 -0.00000 -1.00000" range="-1.48353 0.08727" />
				<include file="output/Unknown/Kitchen_Sink/Door_08/cvx/Door_08_body.xml" />
			</body>
			<body name="Kitchen_Sink/Drawer_02" pos="0.364019 -0.969328 0.683747" quat="1.000000 0.000000 0.000000 0.000000">
				<joint name="Kitchen_Sink/PhysicsConstraint_drawer_02_x_prismatic" type="slide" pos="0.32621 -0.01832 0.08226" axis="1.00000 0.00000 -0.00000" range="-0.25000 0.25000" />
				<include file="output/Unknown/Kitchen_Sink/Drawer_02/cvx/Drawer_02_body.xml" />
			</body>
			<body name="Kitchen_Sink/Door_07" pos="0.638378 0.568577 0.490345" quat="1.000000 0.000000 0.000000 0.000000">
				<joint name="Kitchen_Sink/PhysicsConstraint_door_07_x_revolute" type="hinge" pos="0.00000 0.00000 0.00000" axis="-0.00000 0.00000 -1.00000" range="-0.08727 1.48353" />
				<include file="output/Unknown/Kitchen_Sink/Door_07/cvx/Door_07_body.xml" />
			</body>
			<body name="Kitchen_Sink/Drawer_04" pos="0.402261 1.791574 0.162021" quat="1.000000 0.000000 0.000000 0.000000">
				<joint name="Kitchen_Sink/PhysicsConstraint_drawer_04_x_prismatic" type="slide" pos="0.28560 -0.00765 0.13714" axis="1.00000 0.00000 -0.00000" range="-0.25000 0.25000" />
				<include file="output/Unknown/Kitchen_Sink/Drawer_04/cvx/Drawer_04_body.xml" />
			</body>
			<body name="Kitchen_Sink/Drawer_03" pos="0.404764 1.790787 0.442530" quat="1.000000 0.000000 0.000000 0.000000">
				<joint name="Kitchen_Sink/PhysicsConstraint_drawer_03_x_prismatic" type="slide" pos="0.28309 -0.00187 0.13326" axis="1.00000 0.00000 -0.00000" range="-0.25000 0.25000" />
				<include file="output/Unknown/Kitchen_Sink/Drawer_03/cvx/Drawer_03_body.xml" />
			</body>
			<include file="output/Unknown/Kitchen_Sink/Kitchen_Sink_Base/cvx/Kitchen_Sink_Base_body.xml" />
			<body name="Kitchen_Sink/Drawer_01" pos="0.363330 -1.795013 0.683623" quat="1.000000 0.000000 0.000000 0.000000">
				<joint name="Kitchen_Sink/PhysicsConstraint_drawer_01_x_prismatic" type="slide" pos="0.32690 -0.01748 0.06713" axis="1.00000 0.00000 -0.00000" range="-0.25000 0.25000" />
				<include file="output/Unknown/Kitchen_Sink/Drawer_01/cvx/Drawer_01_body.xml" />
			</body>
			<body name="Kitchen_Sink/Door_05" pos="0.638378 -0.540102 0.357177" quat="1.000000 0.000000 0.000000 0.000000">
				<joint name="Kitchen_Sink/PhysicsConstraint_door_05_x_revolute" type="hinge" pos="0.00000 0.00000 0.00000" axis="0.00000 -0.00000 -1.00000" range="-0.08727 1.48353" />
				<include file="output/Unknown/Kitchen_Sink/Door_05/cvx/Door_05_body.xml" />
			</body>
			<body name="Kitchen_Sink/Door_02" pos="0.638378 -1.400494 0.413661" quat="1.000000 0.000000 0.000000 0.000000">
				<joint name="Kitchen_Sink/PhysicsConstraint_door_02_x_revolute" type="hinge" pos="0.00000 0.00000 0.00000" axis="-0.00000 0.00000 -1.00000" range="-1.48353 0.08727" />
				<include file="output/Unknown/Kitchen_Sink/Door_02/cvx/Door_02_body.xml" />
			</body>
			<body name="Kitchen_Sink/Door_03" pos="0.638378 -1.370386 0.414228" quat="1.000000 0.000000 0.000000 0.000000">
				<joint name="Kitchen_Sink/PhysicsConstraint_door_03_x_revolute" type="hinge" pos="0.00000 0.00000 0.00000" axis="-0.00000 0.00000 -1.00000" range="-0.08727 1.48353" />
				<include file="output/Unknown/Kitchen_Sink/Door_03/cvx/Door_03_body.xml" />
			</body>
			<body name="Kitchen_Sink/Door_04" pos="0.638378 -0.571165 0.414228" quat="1.000000 0.000000 0.000000 0.000000">
				<joint name="Kitchen_Sink/PhysicsConstraint_door_04_x_revolute" type="hinge" pos="0.00000 0.00000 0.00000" axis="0.00000 -0.00000 -1.00000" range="-1.48353 0.08727" />
				<include file="output/Unknown/Kitchen_Sink/Door_04/cvx/Door_04_body.xml" />
			</body>
		</body>
	</worldbody>
	<contact>
		<exclude body1="Kitchen_Sink/Door_04" body2="Kitchen_Sink/Door_03" />
		<exclude body1="Kitchen_Sink/Door_04" body2="Kitchen_Sink/Door_02" />
		<exclude body1="Kitchen_Sink/Door_04" body2="Kitchen_Sink/Door_05" />
		<exclude body1="Kitchen_Sink/Door_04" body2="Kitchen_Sink/Drawer_01" />
		<exclude body1="Kitchen_Sink/Door_04" body2="Kitchen_Sink/Drawer_03" />
		<exclude body1="Kitchen_Sink/Door_04" body2="Kitchen_Sink/Drawer_04" />
		<exclude body1="Kitchen_Sink/Door_04" body2="Kitchen_Sink/Door_07" />
		<exclude body1="Kitchen_Sink/Door_04" body2="Kitchen_Sink/Drawer_02" />
		<exclude body1="Kitchen_Sink/Door_04" body2="Kitchen_Sink/Door_08" />
		<exclude body1="Kitchen_Sink/Door_04" body2="Kitchen_Sink/Door_06" />
		<exclude body1="Kitchen_Sink/Door_04" body2="Kitchen_Sink/Door_01" />
		<exclude body1="Kitchen_Sink/Door_03" body2="Kitchen_Sink/Door_02" />
		<exclude body1="Kitchen_Sink/Door_03" body2="Kitchen_Sink/Door_05" />
		<exclude body1="Kitchen_Sink/Door_03" body2="Kitchen_Sink/Drawer_01" />
		<exclude body1="Kitchen_Sink/Door_03" body2="Kitchen_Sink/Drawer_03" />
		<exclude body1="Kitchen_Sink/Door_03" body2="Kitchen_Sink/Drawer_04" />
		<exclude body1="Kitchen_Sink/Door_03" body2="Kitchen_Sink/Door_07" />
		<exclude body1="Kitchen_Sink/Door_03" body2="Kitchen_Sink/Drawer_02" />
		<exclude body1="Kitchen_Sink/Door_03" body2="Kitchen_Sink/Door_08" />
		<exclude body1="Kitchen_Sink/Door_03" body2="Kitchen_Sink/Door_06" />
		<exclude body1="Kitchen_Sink/Door_03" body2="Kitchen_Sink/Door_01" />
		<exclude body1="Kitchen_Sink/Door_02" body2="Kitchen_Sink/Door_05" />
		<exclude body1="Kitchen_Sink/Door_02" body2="Kitchen_Sink/Drawer_01" />
		<exclude body1="Kitchen_Sink/Door_02" body2="Kitchen_Sink/Drawer_03" />
		<exclude body1="Kitchen_Sink/Door_02" body2="Kitchen_Sink/Drawer_04" />
		<exclude body1="Kitchen_Sink/Door_02" body2="Kitchen_Sink/Door_07" />
		<exclude body1="Kitchen_Sink/Door_02" body2="Kitchen_Sink/Drawer_02" />
		<exclude body1="Kitchen_Sink/Door_02" body2="Kitchen_Sink/Door_08" />
		<exclude body1="Kitchen_Sink/Door_02" body2="Kitchen_Sink/Door_06" />
		<exclude body1="Kitchen_Sink/Door_02" body2="Kitchen_Sink/Door_01" />
		<exclude body1="Kitchen_Sink/Door_05" body2="Kitchen_Sink/Drawer_01" />
		<exclude body1="Kitchen_Sink/Door_05" body2="Kitchen_Sink/Drawer_03" />
		<exclude body1="Kitchen_Sink/Door_05" body2="Kitchen_Sink/Drawer_04" />
		<exclude body1="Kitchen_Sink/Door_05" body2="Kitchen_Sink/Door_07" />
		<exclude body1="Kitchen_Sink/Door_05" body2="Kitchen_Sink/Drawer_02" />
		<exclude body1="Kitchen_Sink/Door_05" body2="Kitchen_Sink/Door_08" />
		<exclude body1="Kitchen_Sink/Door_05" body2="Kitchen_Sink/Door_06" />
		<exclude body1="Kitchen_Sink/Door_05" body2="Kitchen_Sink/Door_01" />
		<exclude body1="Kitchen_Sink/Drawer_01" body2="Kitchen_Sink/Drawer_03" />
		<exclude body1="Kitchen_Sink/Drawer_01" body2="Kitchen_Sink/Drawer_04" />
		<exclude body1="Kitchen_Sink/Drawer_01" body2="Kitchen_Sink/Door_07" />
		<exclude body1="Kitchen_Sink/Drawer_01" body2="Kitchen_Sink/Drawer_02" />
		<exclude body1="Kitchen_Sink/Drawer_01" body2="Kitchen_Sink/Door_08" />
		<exclude body1="Kitchen_Sink/Drawer_01" body2="Kitchen_Sink/Door_06" />
		<exclude body1="Kitchen_Sink/Drawer_01" body2="Kitchen_Sink/Door_01" />
		<exclude body1="Kitchen_Sink/Drawer_03" body2="Kitchen_Sink/Drawer_04" />
		<exclude body1="Kitchen_Sink/Drawer_03" body2="Kitchen_Sink/Door_07" />
		<exclude body1="Kitchen_Sink/Drawer_03" body2="Kitchen_Sink/Drawer_02" />
		<exclude body1="Kitchen_Sink/Drawer_03" body2="Kitchen_Sink/Door_08" />
		<exclude body1="Kitchen_Sink/Drawer_03" body2="Kitchen_Sink/Door_06" />
		<exclude body1="Kitchen_Sink/Drawer_03" body2="Kitchen_Sink/Door_01" />
		<exclude body1="Kitchen_Sink/Drawer_04" body2="Kitchen_Sink/Door_07" />
		<exclude body1="Kitchen_Sink/Drawer_04" body2="Kitchen_Sink/Drawer_02" />
		<exclude body1="Kitchen_Sink/Drawer_04" body2="Kitchen_Sink/Door_08" />
		<exclude body1="Kitchen_Sink/Drawer_04" body2="Kitchen_Sink/Door_06" />
		<exclude body1="Kitchen_Sink/Drawer_04" body2="Kitchen_Sink/Door_01" />
		<exclude body1="Kitchen_Sink/Door_07" body2="Kitchen_Sink/Drawer_02" />
		<exclude body1="Kitchen_Sink/Door_07" body2="Kitchen_Sink/Door_08" />
		<exclude body1="Kitchen_Sink/Door_07" body2="Kitchen_Sink/Door_06" />
		<exclude body1="Kitchen_Sink/Door_07" body2="Kitchen_Sink/Door_01" />
		<exclude body1="Kitchen_Sink/Drawer_02" body2="Kitchen_Sink/Door_08" />
		<exclude body1="Kitchen_Sink/Drawer_02" body2="Kitchen_Sink/Door_06" />
		<exclude body1="Kitchen_Sink/Drawer_02" body2="Kitchen_Sink/Door_01" />
		<exclude body1="Kitchen_Sink/Door_08" body2="Kitchen_Sink/Door_06" />
		<exclude body1="Kitchen_Sink/Door_08" body2="Kitchen_Sink/Door_01" />
		<exclude body1="Kitchen_Sink/Door_06" body2="Kitchen_Sink/Door_01" />
	</contact>
</mujoco>